2025-04-01 14:04:29,698 - ERROR - Error loading model: no such table: hardware_api_modeltraininghistory
2025-04-01 14:05:18,621 - ERROR - Error loading model: no such table: hardware_api_modeltraininghistory
2025-04-01 14:05:59,302 - ERROR - Error loading model: no such table: hardware_api_modeltraininghistory
2025-04-01 14:07:02,503 - ERROR - Error loading model: no such table: hardware_api_modeltraininghistory
2025-04-01 14:12:35,482 - ERROR - Error loading model: no such table: hardware_api_modeltraininghistory
2025-04-01 14:16:29,998 - ERROR - Error loading model: no such table: hardware_api_modeltraininghistory
2025-04-01 14:17:35,890 - INFO - C:\Users\91984\Downloads\CSSS\hardware_monitor_project\hardware_monitor_backend\hardware_monitor_project\wsgi.py changed, reloading.
2025-04-01 14:17:38,528 - ERROR - Error loading model: no such table: hardware_api_modeltraininghistory
2025-04-01 14:17:47,661 - WARNING - Not Found: /
2025-04-01 14:17:47,893 - WARNING - Not Found: /favicon.ico
2025-04-01 14:23:07,110 - WARNING - Forbidden: /api/dashboard/
2025-04-01 14:23:07,116 - WARNING - Forbidden: /api/issues/unresolved/
2025-04-01 14:23:07,118 - WARNING - Forbidden: /api/metrics/latest/
2025-04-01 14:23:07,150 - WARNING - Forbidden: /api/issues/unresolved/
2025-04-01 14:23:07,182 - WARNING - Forbidden: /api/dashboard/
2025-04-01 14:23:07,186 - WARNING - Forbidden: /api/metrics/latest/
2025-04-01 14:23:11,435 - WARNING - Forbidden: /api/metrics/latest/
2025-04-01 14:23:11,441 - WARNING - Forbidden: /api/dashboard/
2025-04-01 14:23:11,443 - WARNING - Forbidden: /api/issues/unresolved/
2025-04-01 14:23:41,596 - WARNING - Forbidden: /api/metrics/latest/
2025-04-01 14:23:41,601 - WARNING - Forbidden: /api/dashboard/
2025-04-01 14:23:41,603 - WARNING - Forbidden: /api/issues/unresolved/
2025-04-01 14:23:44,407 - WARNING - Forbidden: /api/metrics/statistics/
2025-04-01 14:23:44,409 - WARNING - Forbidden: /api/metrics/
2025-04-01 14:23:44,412 - WARNING - Forbidden: /api/metrics/
2025-04-01 14:23:44,426 - WARNING - Forbidden: /api/metrics/statistics/
2025-04-01 14:23:46,291 - WARNING - Forbidden: /api/metrics/latest/
2025-04-01 14:23:46,292 - WARNING - Forbidden: /api/dashboard/
2025-04-01 14:23:46,296 - WARNING - Forbidden: /api/metrics/latest/
2025-04-01 14:23:46,301 - WARNING - Forbidden: /api/dashboard/
2025-04-01 14:23:55,840 - WARNING - Forbidden: /api/training/train/
2025-04-01 14:24:13,404 - WARNING - Forbidden: /api/training/train/
2025-04-01 14:24:13,871 - WARNING - Not Found: /favicon.ico
2025-04-01 14:53:03,968 - WARNING - Forbidden: /api/
2025-04-01 14:53:16,423 - ERROR - Internal Server Error: /admin/hardware_api/modeltraininghistory/
Traceback (most recent call last):
  File "C:\Users\91984\AppData\Local\Programs\Python\Python311\Lib\site-packages\django\db\backends\utils.py", line 89, in _execute
    return self.cursor.execute(sql, params)
           ^^^^^^^^^^^^^^^^^^^^^^^^^^^^^^^^
  File "C:\Users\91984\AppData\Local\Programs\Python\Python311\Lib\site-packages\django\db\backends\sqlite3\base.py", line 328, in execute
    return super().execute(query, params)
           ^^^^^^^^^^^^^^^^^^^^^^^^^^^^^^
sqlite3.OperationalError: no such table: hardware_api_modeltraininghistory

The above exception was the direct cause of the following exception:

Traceback (most recent call last):
  File "C:\Users\91984\AppData\Local\Programs\Python\Python311\Lib\site-packages\django\core\handlers\exception.py", line 55, in inner
    response = get_response(request)
               ^^^^^^^^^^^^^^^^^^^^^
  File "C:\Users\91984\AppData\Local\Programs\Python\Python311\Lib\site-packages\django\core\handlers\base.py", line 197, in _get_response
    response = wrapped_callback(request, *callback_args, **callback_kwargs)
               ^^^^^^^^^^^^^^^^^^^^^^^^^^^^^^^^^^^^^^^^^^^^^^^^^^^^^^^^^^^^
  File "C:\Users\91984\AppData\Local\Programs\Python\Python311\Lib\site-packages\django\contrib\admin\options.py", line 688, in wrapper
    return self.admin_site.admin_view(view)(*args, **kwargs)
           ^^^^^^^^^^^^^^^^^^^^^^^^^^^^^^^^^^^^^^^^^^^^^^^^^
  File "C:\Users\91984\AppData\Local\Programs\Python\Python311\Lib\site-packages\django\utils\decorators.py", line 134, in _wrapper_view
    response = view_func(request, *args, **kwargs)
               ^^^^^^^^^^^^^^^^^^^^^^^^^^^^^^^^^^^
  File "C:\Users\91984\AppData\Local\Programs\Python\Python311\Lib\site-packages\django\views\decorators\cache.py", line 62, in _wrapper_view_func
    response = view_func(request, *args, **kwargs)
               ^^^^^^^^^^^^^^^^^^^^^^^^^^^^^^^^^^^
  File "C:\Users\91984\AppData\Local\Programs\Python\Python311\Lib\site-packages\django\contrib\admin\sites.py", line 242, in inner
    return view(request, *args, **kwargs)
           ^^^^^^^^^^^^^^^^^^^^^^^^^^^^^^
  File "C:\Users\91984\AppData\Local\Programs\Python\Python311\Lib\site-packages\django\utils\decorators.py", line 46, in _wrapper
    return bound_method(*args, **kwargs)
           ^^^^^^^^^^^^^^^^^^^^^^^^^^^^^
  File "C:\Users\91984\AppData\Local\Programs\Python\Python311\Lib\site-packages\django\utils\decorators.py", line 134, in _wrapper_view
    response = view_func(request, *args, **kwargs)
               ^^^^^^^^^^^^^^^^^^^^^^^^^^^^^^^^^^^
  File "C:\Users\91984\AppData\Local\Programs\Python\Python311\Lib\site-packages\django\contrib\admin\options.py", line 1926, in changelist_view
    cl = self.get_changelist_instance(request)
         ^^^^^^^^^^^^^^^^^^^^^^^^^^^^^^^^^^^^^
  File "C:\Users\91984\AppData\Local\Programs\Python\Python311\Lib\site-packages\django\contrib\admin\options.py", line 836, in get_changelist_instance
    return ChangeList(
           ^^^^^^^^^^^
  File "C:\Users\91984\AppData\Local\Programs\Python\Python311\Lib\site-packages\django\contrib\admin\views\main.py", line 123, in __init__
    self.get_results(request)
  File "C:\Users\91984\AppData\Local\Programs\Python\Python311\Lib\site-packages\django\contrib\admin\views\main.py", line 279, in get_results
    result_count = paginator.count
                   ^^^^^^^^^^^^^^^
  File "C:\Users\91984\AppData\Local\Programs\Python\Python311\Lib\site-packages\django\utils\functional.py", line 57, in __get__
    res = instance.__dict__[self.name] = self.func(instance)
                                         ^^^^^^^^^^^^^^^^^^^
  File "C:\Users\91984\AppData\Local\Programs\Python\Python311\Lib\site-packages\django\core\paginator.py", line 93, in count
    return c()
           ^^^
  File "C:\Users\91984\AppData\Local\Programs\Python\Python311\Lib\site-packages\django\db\models\query.py", line 608, in count
    return self.query.get_count(using=self.db)
           ^^^^^^^^^^^^^^^^^^^^^^^^^^^^^^^^^^^
  File "C:\Users\91984\AppData\Local\Programs\Python\Python311\Lib\site-packages\django\db\models\sql\query.py", line 568, in get_count
    return obj.get_aggregation(using, {"__count": Count("*")})["__count"]
           ^^^^^^^^^^^^^^^^^^^^^^^^^^^^^^^^^^^^^^^^^^^^^^^^^^^
  File "C:\Users\91984\AppData\Local\Programs\Python\Python311\Lib\site-packages\django\db\models\sql\query.py", line 554, in get_aggregation
    result = compiler.execute_sql(SINGLE)
             ^^^^^^^^^^^^^^^^^^^^^^^^^^^^
  File "C:\Users\91984\AppData\Local\Programs\Python\Python311\Lib\site-packages\django\db\models\sql\compiler.py", line 1562, in execute_sql
    cursor.execute(sql, params)
  File "C:\Users\91984\AppData\Local\Programs\Python\Python311\Lib\site-packages\django\db\backends\utils.py", line 102, in execute
    return super().execute(sql, params)
           ^^^^^^^^^^^^^^^^^^^^^^^^^^^^
  File "C:\Users\91984\AppData\Local\Programs\Python\Python311\Lib\site-packages\django\db\backends\utils.py", line 67, in execute
    return self._execute_with_wrappers(
           ^^^^^^^^^^^^^^^^^^^^^^^^^^^^
  File "C:\Users\91984\AppData\Local\Programs\Python\Python311\Lib\site-packages\django\db\backends\utils.py", line 80, in _execute_with_wrappers
    return executor(sql, params, many, context)
           ^^^^^^^^^^^^^^^^^^^^^^^^^^^^^^^^^^^^
  File "C:\Users\91984\AppData\Local\Programs\Python\Python311\Lib\site-packages\django\db\backends\utils.py", line 84, in _execute
    with self.db.wrap_database_errors:
  File "C:\Users\91984\AppData\Local\Programs\Python\Python311\Lib\site-packages\django\db\utils.py", line 91, in __exit__
    raise dj_exc_value.with_traceback(traceback) from exc_value
  File "C:\Users\91984\AppData\Local\Programs\Python\Python311\Lib\site-packages\django\db\backends\utils.py", line 89, in _execute
    return self.cursor.execute(sql, params)
           ^^^^^^^^^^^^^^^^^^^^^^^^^^^^^^^^
  File "C:\Users\91984\AppData\Local\Programs\Python\Python311\Lib\site-packages\django\db\backends\sqlite3\base.py", line 328, in execute
    return super().execute(query, params)
           ^^^^^^^^^^^^^^^^^^^^^^^^^^^^^^
django.db.utils.OperationalError: no such table: hardware_api_modeltraininghistory
2025-04-01 15:24:40,300 - WARNING - Forbidden: /api/metrics/latest/
2025-04-01 15:24:40,306 - WARNING - Forbidden: /api/dashboard/
2025-04-01 15:24:40,323 - WARNING - Forbidden: /api/metrics/latest/
2025-04-01 15:24:40,358 - WARNING - Forbidden: /api/dashboard/
2025-04-01 15:24:44,890 - WARNING - Forbidden: /api/metrics/statistics/
2025-04-01 15:24:44,891 - WARNING - Forbidden: /api/metrics/
2025-04-01 15:24:44,891 - WARNING - Forbidden: /api/metrics/
2025-04-01 15:24:44,908 - WARNING - Forbidden: /api/metrics/statistics/
2025-04-01 15:24:46,335 - WARNING - Forbidden: /api/metrics/latest/
2025-04-01 15:24:46,340 - WARNING - Forbidden: /api/dashboard/
2025-04-01 15:24:46,345 - WARNING - Forbidden: /api/issues/unresolved/
2025-04-01 15:24:46,373 - WARNING - Forbidden: /api/metrics/latest/
2025-04-01 15:24:46,410 - WARNING - Forbidden: /api/dashboard/
2025-04-01 15:24:46,438 - WARNING - Forbidden: /api/issues/unresolved/
2025-04-01 15:24:48,668 - WARNING - Forbidden: /api/metrics/collect/
2025-04-01 15:25:10,122 - WARNING - Forbidden: /api/
2025-04-01 15:25:16,609 - WARNING - Forbidden: /api/metrics/latest/
2025-04-01 15:25:16,612 - WARNING - Forbidden: /api/dashboard/
2025-04-01 15:25:16,615 - WARNING - Forbidden: /api/issues/unresolved/
2025-04-01 15:25:46,274 - WARNING - Forbidden: /api/metrics/latest/
2025-04-01 15:25:46,276 - WARNING - Forbidden: /api/dashboard/
2025-04-01 15:25:46,278 - WARNING - Forbidden: /api/issues/unresolved/
2025-04-01 15:26:16,276 - WARNING - Forbidden: /api/metrics/latest/
2025-04-01 15:26:16,278 - WARNING - Forbidden: /api/dashboard/
2025-04-01 15:26:16,281 - WARNING - Forbidden: /api/issues/unresolved/
2025-04-01 15:26:46,281 - WARNING - Forbidden: /api/metrics/latest/
2025-04-01 15:26:46,282 - WARNING - Forbidden: /api/dashboard/
2025-04-01 15:26:46,283 - WARNING - Forbidden: /api/issues/unresolved/
2025-04-01 15:27:26,581 - WARNING - Forbidden: /api/metrics/latest/
2025-04-01 15:27:26,586 - WARNING - Forbidden: /api/dashboard/
2025-04-01 15:27:26,587 - WARNING - Forbidden: /api/issues/unresolved/
2025-04-01 15:28:26,279 - WARNING - Forbidden: /api/metrics/latest/
2025-04-01 15:28:26,282 - WARNING - Forbidden: /api/dashboard/
2025-04-01 15:28:26,283 - WARNING - Forbidden: /api/issues/unresolved/
2025-04-01 15:29:26,580 - WARNING - Forbidden: /api/metrics/latest/
2025-04-01 15:29:26,582 - WARNING - Forbidden: /api/dashboard/
2025-04-01 15:29:26,588 - WARNING - Forbidden: /api/issues/unresolved/
2025-04-01 15:29:49,842 - INFO - C:\Users\91984\Downloads\CSSS\hardware_monitor_project\hardware_monitor_backend\hardware_api\views.py changed, reloading.
2025-04-01 15:29:56,178 - ERROR - Error loading model: no such table: hardware_api_modeltraininghistory
2025-04-01 15:30:02,278 - ERROR - Internal Server Error: /api/dashboard/
Traceback (most recent call last):
  File "C:\Users\91984\AppData\Local\Programs\Python\Python311\Lib\site-packages\django\db\backends\utils.py", line 89, in _execute
    return self.cursor.execute(sql, params)
           ^^^^^^^^^^^^^^^^^^^^^^^^^^^^^^^^
  File "C:\Users\91984\AppData\Local\Programs\Python\Python311\Lib\site-packages\django\db\backends\sqlite3\base.py", line 328, in execute
    return super().execute(query, params)
           ^^^^^^^^^^^^^^^^^^^^^^^^^^^^^^
sqlite3.OperationalError: no such table: hardware_api_systemmetric

The above exception was the direct cause of the following exception:

Traceback (most recent call last):
  File "C:\Users\91984\AppData\Local\Programs\Python\Python311\Lib\site-packages\django\core\handlers\exception.py", line 55, in inner
    response = get_response(request)
               ^^^^^^^^^^^^^^^^^^^^^
  File "C:\Users\91984\AppData\Local\Programs\Python\Python311\Lib\site-packages\django\core\handlers\base.py", line 197, in _get_response
    response = wrapped_callback(request, *callback_args, **callback_kwargs)
               ^^^^^^^^^^^^^^^^^^^^^^^^^^^^^^^^^^^^^^^^^^^^^^^^^^^^^^^^^^^^
  File "C:\Users\91984\AppData\Local\Programs\Python\Python311\Lib\site-packages\django\views\decorators\csrf.py", line 56, in wrapper_view
    return view_func(*args, **kwargs)
           ^^^^^^^^^^^^^^^^^^^^^^^^^^
  File "C:\Users\91984\AppData\Local\Programs\Python\Python311\Lib\site-packages\django\views\generic\base.py", line 104, in view
    return self.dispatch(request, *args, **kwargs)
           ^^^^^^^^^^^^^^^^^^^^^^^^^^^^^^^^^^^^^^^
  File "C:\Users\91984\AppData\Local\Programs\Python\Python311\Lib\site-packages\rest_framework\views.py", line 509, in dispatch
    response = self.handle_exception(exc)
               ^^^^^^^^^^^^^^^^^^^^^^^^^^
  File "C:\Users\91984\AppData\Local\Programs\Python\Python311\Lib\site-packages\rest_framework\views.py", line 469, in handle_exception
    self.raise_uncaught_exception(exc)
  File "C:\Users\91984\AppData\Local\Programs\Python\Python311\Lib\site-packages\rest_framework\views.py", line 480, in raise_uncaught_exception
    raise exc
  File "C:\Users\91984\AppData\Local\Programs\Python\Python311\Lib\site-packages\rest_framework\views.py", line 506, in dispatch
    response = handler(request, *args, **kwargs)
               ^^^^^^^^^^^^^^^^^^^^^^^^^^^^^^^^^
  File "C:\Users\91984\Downloads\CSSS\hardware_monitor_project\hardware_monitor_backend\hardware_api\views.py", line 359, in get
    summary = hardware_monitor.get_system_summary()
              ^^^^^^^^^^^^^^^^^^^^^^^^^^^^^^^^^^^^^
  File "C:\Users\91984\Downloads\CSSS\hardware_monitor_project\hardware_monitor_backend\hardware_api\hardware_monitor.py", line 406, in get_system_summary
    cpu_trend = [m.cpu_percent for m in metrics_history]
                ^^^^^^^^^^^^^^^^^^^^^^^^^^^^^^^^^^^^^^^^
  File "C:\Users\91984\AppData\Local\Programs\Python\Python311\Lib\site-packages\django\db\models\query.py", line 398, in __iter__
    self._fetch_all()
  File "C:\Users\91984\AppData\Local\Programs\Python\Python311\Lib\site-packages\django\db\models\query.py", line 1881, in _fetch_all
    self._result_cache = list(self._iterable_class(self))
                         ^^^^^^^^^^^^^^^^^^^^^^^^^^^^^^^^
  File "C:\Users\91984\AppData\Local\Programs\Python\Python311\Lib\site-packages\django\db\models\query.py", line 91, in __iter__
    results = compiler.execute_sql(
              ^^^^^^^^^^^^^^^^^^^^^
  File "C:\Users\91984\AppData\Local\Programs\Python\Python311\Lib\site-packages\django\db\models\sql\compiler.py", line 1562, in execute_sql
    cursor.execute(sql, params)
  File "C:\Users\91984\AppData\Local\Programs\Python\Python311\Lib\site-packages\django\db\backends\utils.py", line 102, in execute
    return super().execute(sql, params)
           ^^^^^^^^^^^^^^^^^^^^^^^^^^^^
  File "C:\Users\91984\AppData\Local\Programs\Python\Python311\Lib\site-packages\django\db\backends\utils.py", line 67, in execute
    return self._execute_with_wrappers(
           ^^^^^^^^^^^^^^^^^^^^^^^^^^^^
  File "C:\Users\91984\AppData\Local\Programs\Python\Python311\Lib\site-packages\django\db\backends\utils.py", line 80, in _execute_with_wrappers
    return executor(sql, params, many, context)
           ^^^^^^^^^^^^^^^^^^^^^^^^^^^^^^^^^^^^
  File "C:\Users\91984\AppData\Local\Programs\Python\Python311\Lib\site-packages\django\db\backends\utils.py", line 84, in _execute
    with self.db.wrap_database_errors:
  File "C:\Users\91984\AppData\Local\Programs\Python\Python311\Lib\site-packages\django\db\utils.py", line 91, in __exit__
    raise dj_exc_value.with_traceback(traceback) from exc_value
  File "C:\Users\91984\AppData\Local\Programs\Python\Python311\Lib\site-packages\django\db\backends\utils.py", line 89, in _execute
    return self.cursor.execute(sql, params)
           ^^^^^^^^^^^^^^^^^^^^^^^^^^^^^^^^
  File "C:\Users\91984\AppData\Local\Programs\Python\Python311\Lib\site-packages\django\db\backends\sqlite3\base.py", line 328, in execute
    return super().execute(query, params)
           ^^^^^^^^^^^^^^^^^^^^^^^^^^^^^^
django.db.utils.OperationalError: no such table: hardware_api_systemmetric
2025-04-01 15:30:02,299 - ERROR - Internal Server Error: /api/metrics/latest/
Traceback (most recent call last):
  File "C:\Users\91984\AppData\Local\Programs\Python\Python311\Lib\site-packages\django\db\backends\utils.py", line 89, in _execute
    return self.cursor.execute(sql, params)
           ^^^^^^^^^^^^^^^^^^^^^^^^^^^^^^^^
  File "C:\Users\91984\AppData\Local\Programs\Python\Python311\Lib\site-packages\django\db\backends\sqlite3\base.py", line 328, in execute
    return super().execute(query, params)
           ^^^^^^^^^^^^^^^^^^^^^^^^^^^^^^
sqlite3.OperationalError: no such table: hardware_api_systemmetric

The above exception was the direct cause of the following exception:

Traceback (most recent call last):
  File "C:\Users\91984\AppData\Local\Programs\Python\Python311\Lib\site-packages\django\core\handlers\exception.py", line 55, in inner
    response = get_response(request)
               ^^^^^^^^^^^^^^^^^^^^^
  File "C:\Users\91984\AppData\Local\Programs\Python\Python311\Lib\site-packages\django\core\handlers\base.py", line 197, in _get_response
    response = wrapped_callback(request, *callback_args, **callback_kwargs)
               ^^^^^^^^^^^^^^^^^^^^^^^^^^^^^^^^^^^^^^^^^^^^^^^^^^^^^^^^^^^^
  File "C:\Users\91984\AppData\Local\Programs\Python\Python311\Lib\site-packages\django\views\decorators\csrf.py", line 56, in wrapper_view
    return view_func(*args, **kwargs)
           ^^^^^^^^^^^^^^^^^^^^^^^^^^
  File "C:\Users\91984\AppData\Local\Programs\Python\Python311\Lib\site-packages\rest_framework\viewsets.py", line 125, in view
    return self.dispatch(request, *args, **kwargs)
           ^^^^^^^^^^^^^^^^^^^^^^^^^^^^^^^^^^^^^^^
  File "C:\Users\91984\AppData\Local\Programs\Python\Python311\Lib\site-packages\rest_framework\views.py", line 509, in dispatch
    response = self.handle_exception(exc)
               ^^^^^^^^^^^^^^^^^^^^^^^^^^
  File "C:\Users\91984\AppData\Local\Programs\Python\Python311\Lib\site-packages\rest_framework\views.py", line 469, in handle_exception
    self.raise_uncaught_exception(exc)
  File "C:\Users\91984\AppData\Local\Programs\Python\Python311\Lib\site-packages\rest_framework\views.py", line 480, in raise_uncaught_exception
    raise exc
  File "C:\Users\91984\AppData\Local\Programs\Python\Python311\Lib\site-packages\rest_framework\views.py", line 506, in dispatch
    response = handler(request, *args, **kwargs)
               ^^^^^^^^^^^^^^^^^^^^^^^^^^^^^^^^^
  File "C:\Users\91984\Downloads\CSSS\hardware_monitor_project\hardware_monitor_backend\hardware_api\views.py", line 202, in latest
    latest_metric = SystemMetric.objects.order_by('-timestamp').first()
                    ^^^^^^^^^^^^^^^^^^^^^^^^^^^^^^^^^^^^^^^^^^^^^^^^^^^
  File "C:\Users\91984\AppData\Local\Programs\Python\Python311\Lib\site-packages\django\db\models\query.py", line 1057, in first
    for obj in queryset[:1]:
  File "C:\Users\91984\AppData\Local\Programs\Python\Python311\Lib\site-packages\django\db\models\query.py", line 398, in __iter__
    self._fetch_all()
  File "C:\Users\91984\AppData\Local\Programs\Python\Python311\Lib\site-packages\django\db\models\query.py", line 1881, in _fetch_all
    self._result_cache = list(self._iterable_class(self))
                         ^^^^^^^^^^^^^^^^^^^^^^^^^^^^^^^^
  File "C:\Users\91984\AppData\Local\Programs\Python\Python311\Lib\site-packages\django\db\models\query.py", line 91, in __iter__
    results = compiler.execute_sql(
              ^^^^^^^^^^^^^^^^^^^^^
  File "C:\Users\91984\AppData\Local\Programs\Python\Python311\Lib\site-packages\django\db\models\sql\compiler.py", line 1562, in execute_sql
    cursor.execute(sql, params)
  File "C:\Users\91984\AppData\Local\Programs\Python\Python311\Lib\site-packages\django\db\backends\utils.py", line 102, in execute
    return super().execute(sql, params)
           ^^^^^^^^^^^^^^^^^^^^^^^^^^^^
  File "C:\Users\91984\AppData\Local\Programs\Python\Python311\Lib\site-packages\django\db\backends\utils.py", line 67, in execute
    return self._execute_with_wrappers(
           ^^^^^^^^^^^^^^^^^^^^^^^^^^^^
  File "C:\Users\91984\AppData\Local\Programs\Python\Python311\Lib\site-packages\django\db\backends\utils.py", line 80, in _execute_with_wrappers
    return executor(sql, params, many, context)
           ^^^^^^^^^^^^^^^^^^^^^^^^^^^^^^^^^^^^
  File "C:\Users\91984\AppData\Local\Programs\Python\Python311\Lib\site-packages\django\db\backends\utils.py", line 84, in _execute
    with self.db.wrap_database_errors:
  File "C:\Users\91984\AppData\Local\Programs\Python\Python311\Lib\site-packages\django\db\utils.py", line 91, in __exit__
    raise dj_exc_value.with_traceback(traceback) from exc_value
  File "C:\Users\91984\AppData\Local\Programs\Python\Python311\Lib\site-packages\django\db\backends\utils.py", line 89, in _execute
    return self.cursor.execute(sql, params)
           ^^^^^^^^^^^^^^^^^^^^^^^^^^^^^^^^
  File "C:\Users\91984\AppData\Local\Programs\Python\Python311\Lib\site-packages\django\db\backends\sqlite3\base.py", line 328, in execute
    return super().execute(query, params)
           ^^^^^^^^^^^^^^^^^^^^^^^^^^^^^^
django.db.utils.OperationalError: no such table: hardware_api_systemmetric
2025-04-01 15:30:02,481 - ERROR - Internal Server Error: /api/issues/unresolved/
Traceback (most recent call last):
  File "C:\Users\91984\AppData\Local\Programs\Python\Python311\Lib\site-packages\django\db\backends\utils.py", line 89, in _execute
    return self.cursor.execute(sql, params)
           ^^^^^^^^^^^^^^^^^^^^^^^^^^^^^^^^
  File "C:\Users\91984\AppData\Local\Programs\Python\Python311\Lib\site-packages\django\db\backends\sqlite3\base.py", line 328, in execute
    return super().execute(query, params)
           ^^^^^^^^^^^^^^^^^^^^^^^^^^^^^^
sqlite3.OperationalError: no such table: hardware_api_hardwareissue

The above exception was the direct cause of the following exception:

Traceback (most recent call last):
  File "C:\Users\91984\AppData\Local\Programs\Python\Python311\Lib\site-packages\django\core\handlers\exception.py", line 55, in inner
    response = get_response(request)
               ^^^^^^^^^^^^^^^^^^^^^
  File "C:\Users\91984\AppData\Local\Programs\Python\Python311\Lib\site-packages\django\core\handlers\base.py", line 197, in _get_response
    response = wrapped_callback(request, *callback_args, **callback_kwargs)
               ^^^^^^^^^^^^^^^^^^^^^^^^^^^^^^^^^^^^^^^^^^^^^^^^^^^^^^^^^^^^
  File "C:\Users\91984\AppData\Local\Programs\Python\Python311\Lib\site-packages\django\views\decorators\csrf.py", line 56, in wrapper_view
    return view_func(*args, **kwargs)
           ^^^^^^^^^^^^^^^^^^^^^^^^^^
  File "C:\Users\91984\AppData\Local\Programs\Python\Python311\Lib\site-packages\rest_framework\viewsets.py", line 125, in view
    return self.dispatch(request, *args, **kwargs)
           ^^^^^^^^^^^^^^^^^^^^^^^^^^^^^^^^^^^^^^^
  File "C:\Users\91984\AppData\Local\Programs\Python\Python311\Lib\site-packages\rest_framework\views.py", line 509, in dispatch
    response = self.handle_exception(exc)
               ^^^^^^^^^^^^^^^^^^^^^^^^^^
  File "C:\Users\91984\AppData\Local\Programs\Python\Python311\Lib\site-packages\rest_framework\views.py", line 469, in handle_exception
    self.raise_uncaught_exception(exc)
  File "C:\Users\91984\AppData\Local\Programs\Python\Python311\Lib\site-packages\rest_framework\views.py", line 480, in raise_uncaught_exception
    raise exc
  File "C:\Users\91984\AppData\Local\Programs\Python\Python311\Lib\site-packages\rest_framework\views.py", line 506, in dispatch
    response = handler(request, *args, **kwargs)
               ^^^^^^^^^^^^^^^^^^^^^^^^^^^^^^^^^
  File "C:\Users\91984\Downloads\CSSS\hardware_monitor_project\hardware_monitor_backend\hardware_api\views.py", line 78, in unresolved
    return Response(serializer.data)
                    ^^^^^^^^^^^^^^^
  File "C:\Users\91984\AppData\Local\Programs\Python\Python311\Lib\site-packages\rest_framework\serializers.py", line 768, in data
    ret = super().data
          ^^^^^^^^^^^^
  File "C:\Users\91984\AppData\Local\Programs\Python\Python311\Lib\site-packages\rest_framework\serializers.py", line 253, in data
    self._data = self.to_representation(self.instance)
                 ^^^^^^^^^^^^^^^^^^^^^^^^^^^^^^^^^^^^^
  File "C:\Users\91984\AppData\Local\Programs\Python\Python311\Lib\site-packages\rest_framework\serializers.py", line 686, in to_representation
    return [
           ^
  File "C:\Users\91984\AppData\Local\Programs\Python\Python311\Lib\site-packages\django\db\models\query.py", line 398, in __iter__
    self._fetch_all()
  File "C:\Users\91984\AppData\Local\Programs\Python\Python311\Lib\site-packages\django\db\models\query.py", line 1881, in _fetch_all
    self._result_cache = list(self._iterable_class(self))
                         ^^^^^^^^^^^^^^^^^^^^^^^^^^^^^^^^
  File "C:\Users\91984\AppData\Local\Programs\Python\Python311\Lib\site-packages\django\db\models\query.py", line 91, in __iter__
    results = compiler.execute_sql(
              ^^^^^^^^^^^^^^^^^^^^^
  File "C:\Users\91984\AppData\Local\Programs\Python\Python311\Lib\site-packages\django\db\models\sql\compiler.py", line 1562, in execute_sql
    cursor.execute(sql, params)
  File "C:\Users\91984\AppData\Local\Programs\Python\Python311\Lib\site-packages\django\db\backends\utils.py", line 102, in execute
    return super().execute(sql, params)
           ^^^^^^^^^^^^^^^^^^^^^^^^^^^^
  File "C:\Users\91984\AppData\Local\Programs\Python\Python311\Lib\site-packages\django\db\backends\utils.py", line 67, in execute
    return self._execute_with_wrappers(
           ^^^^^^^^^^^^^^^^^^^^^^^^^^^^
  File "C:\Users\91984\AppData\Local\Programs\Python\Python311\Lib\site-packages\django\db\backends\utils.py", line 80, in _execute_with_wrappers
    return executor(sql, params, many, context)
           ^^^^^^^^^^^^^^^^^^^^^^^^^^^^^^^^^^^^
  File "C:\Users\91984\AppData\Local\Programs\Python\Python311\Lib\site-packages\django\db\backends\utils.py", line 84, in _execute
    with self.db.wrap_database_errors:
  File "C:\Users\91984\AppData\Local\Programs\Python\Python311\Lib\site-packages\django\db\utils.py", line 91, in __exit__
    raise dj_exc_value.with_traceback(traceback) from exc_value
  File "C:\Users\91984\AppData\Local\Programs\Python\Python311\Lib\site-packages\django\db\backends\utils.py", line 89, in _execute
    return self.cursor.execute(sql, params)
           ^^^^^^^^^^^^^^^^^^^^^^^^^^^^^^^^
  File "C:\Users\91984\AppData\Local\Programs\Python\Python311\Lib\site-packages\django\db\backends\sqlite3\base.py", line 328, in execute
    return super().execute(query, params)
           ^^^^^^^^^^^^^^^^^^^^^^^^^^^^^^
django.db.utils.OperationalError: no such table: hardware_api_hardwareissue
2025-04-01 15:30:16,349 - ERROR - Internal Server Error: /api/metrics/latest/
Traceback (most recent call last):
  File "C:\Users\91984\AppData\Local\Programs\Python\Python311\Lib\site-packages\django\db\backends\utils.py", line 89, in _execute
    return self.cursor.execute(sql, params)
           ^^^^^^^^^^^^^^^^^^^^^^^^^^^^^^^^
  File "C:\Users\91984\AppData\Local\Programs\Python\Python311\Lib\site-packages\django\db\backends\sqlite3\base.py", line 328, in execute
    return super().execute(query, params)
           ^^^^^^^^^^^^^^^^^^^^^^^^^^^^^^
sqlite3.OperationalError: no such table: hardware_api_systemmetric

The above exception was the direct cause of the following exception:

Traceback (most recent call last):
  File "C:\Users\91984\AppData\Local\Programs\Python\Python311\Lib\site-packages\django\core\handlers\exception.py", line 55, in inner
    response = get_response(request)
               ^^^^^^^^^^^^^^^^^^^^^
  File "C:\Users\91984\AppData\Local\Programs\Python\Python311\Lib\site-packages\django\core\handlers\base.py", line 197, in _get_response
    response = wrapped_callback(request, *callback_args, **callback_kwargs)
               ^^^^^^^^^^^^^^^^^^^^^^^^^^^^^^^^^^^^^^^^^^^^^^^^^^^^^^^^^^^^
  File "C:\Users\91984\AppData\Local\Programs\Python\Python311\Lib\site-packages\django\views\decorators\csrf.py", line 56, in wrapper_view
    return view_func(*args, **kwargs)
           ^^^^^^^^^^^^^^^^^^^^^^^^^^
  File "C:\Users\91984\AppData\Local\Programs\Python\Python311\Lib\site-packages\rest_framework\viewsets.py", line 125, in view
    return self.dispatch(request, *args, **kwargs)
           ^^^^^^^^^^^^^^^^^^^^^^^^^^^^^^^^^^^^^^^
  File "C:\Users\91984\AppData\Local\Programs\Python\Python311\Lib\site-packages\rest_framework\views.py", line 509, in dispatch
    response = self.handle_exception(exc)
               ^^^^^^^^^^^^^^^^^^^^^^^^^^
  File "C:\Users\91984\AppData\Local\Programs\Python\Python311\Lib\site-packages\rest_framework\views.py", line 469, in handle_exception
    self.raise_uncaught_exception(exc)
  File "C:\Users\91984\AppData\Local\Programs\Python\Python311\Lib\site-packages\rest_framework\views.py", line 480, in raise_uncaught_exception
    raise exc
  File "C:\Users\91984\AppData\Local\Programs\Python\Python311\Lib\site-packages\rest_framework\views.py", line 506, in dispatch
    response = handler(request, *args, **kwargs)
               ^^^^^^^^^^^^^^^^^^^^^^^^^^^^^^^^^
  File "C:\Users\91984\Downloads\CSSS\hardware_monitor_project\hardware_monitor_backend\hardware_api\views.py", line 202, in latest
    latest_metric = SystemMetric.objects.order_by('-timestamp').first()
                    ^^^^^^^^^^^^^^^^^^^^^^^^^^^^^^^^^^^^^^^^^^^^^^^^^^^
  File "C:\Users\91984\AppData\Local\Programs\Python\Python311\Lib\site-packages\django\db\models\query.py", line 1057, in first
    for obj in queryset[:1]:
  File "C:\Users\91984\AppData\Local\Programs\Python\Python311\Lib\site-packages\django\db\models\query.py", line 398, in __iter__
    self._fetch_all()
  File "C:\Users\91984\AppData\Local\Programs\Python\Python311\Lib\site-packages\django\db\models\query.py", line 1881, in _fetch_all
    self._result_cache = list(self._iterable_class(self))
                         ^^^^^^^^^^^^^^^^^^^^^^^^^^^^^^^^
  File "C:\Users\91984\AppData\Local\Programs\Python\Python311\Lib\site-packages\django\db\models\query.py", line 91, in __iter__
    results = compiler.execute_sql(
              ^^^^^^^^^^^^^^^^^^^^^
  File "C:\Users\91984\AppData\Local\Programs\Python\Python311\Lib\site-packages\django\db\models\sql\compiler.py", line 1562, in execute_sql
    cursor.execute(sql, params)
  File "C:\Users\91984\AppData\Local\Programs\Python\Python311\Lib\site-packages\django\db\backends\utils.py", line 102, in execute
    return super().execute(sql, params)
           ^^^^^^^^^^^^^^^^^^^^^^^^^^^^
  File "C:\Users\91984\AppData\Local\Programs\Python\Python311\Lib\site-packages\django\db\backends\utils.py", line 67, in execute
    return self._execute_with_wrappers(
           ^^^^^^^^^^^^^^^^^^^^^^^^^^^^
  File "C:\Users\91984\AppData\Local\Programs\Python\Python311\Lib\site-packages\django\db\backends\utils.py", line 80, in _execute_with_wrappers
    return executor(sql, params, many, context)
           ^^^^^^^^^^^^^^^^^^^^^^^^^^^^^^^^^^^^
  File "C:\Users\91984\AppData\Local\Programs\Python\Python311\Lib\site-packages\django\db\backends\utils.py", line 84, in _execute
    with self.db.wrap_database_errors:
  File "C:\Users\91984\AppData\Local\Programs\Python\Python311\Lib\site-packages\django\db\utils.py", line 91, in __exit__
    raise dj_exc_value.with_traceback(traceback) from exc_value
  File "C:\Users\91984\AppData\Local\Programs\Python\Python311\Lib\site-packages\django\db\backends\utils.py", line 89, in _execute
    return self.cursor.execute(sql, params)
           ^^^^^^^^^^^^^^^^^^^^^^^^^^^^^^^^
  File "C:\Users\91984\AppData\Local\Programs\Python\Python311\Lib\site-packages\django\db\backends\sqlite3\base.py", line 328, in execute
    return super().execute(query, params)
           ^^^^^^^^^^^^^^^^^^^^^^^^^^^^^^
django.db.utils.OperationalError: no such table: hardware_api_systemmetric
2025-04-01 15:30:16,372 - ERROR - Internal Server Error: /api/issues/unresolved/
Traceback (most recent call last):
  File "C:\Users\91984\AppData\Local\Programs\Python\Python311\Lib\site-packages\django\db\backends\utils.py", line 89, in _execute
    return self.cursor.execute(sql, params)
           ^^^^^^^^^^^^^^^^^^^^^^^^^^^^^^^^
  File "C:\Users\91984\AppData\Local\Programs\Python\Python311\Lib\site-packages\django\db\backends\sqlite3\base.py", line 328, in execute
    return super().execute(query, params)
           ^^^^^^^^^^^^^^^^^^^^^^^^^^^^^^
sqlite3.OperationalError: no such table: hardware_api_hardwareissue

The above exception was the direct cause of the following exception:

Traceback (most recent call last):
  File "C:\Users\91984\AppData\Local\Programs\Python\Python311\Lib\site-packages\django\core\handlers\exception.py", line 55, in inner
    response = get_response(request)
               ^^^^^^^^^^^^^^^^^^^^^
  File "C:\Users\91984\AppData\Local\Programs\Python\Python311\Lib\site-packages\django\core\handlers\base.py", line 197, in _get_response
    response = wrapped_callback(request, *callback_args, **callback_kwargs)
               ^^^^^^^^^^^^^^^^^^^^^^^^^^^^^^^^^^^^^^^^^^^^^^^^^^^^^^^^^^^^
  File "C:\Users\91984\AppData\Local\Programs\Python\Python311\Lib\site-packages\django\views\decorators\csrf.py", line 56, in wrapper_view
    return view_func(*args, **kwargs)
           ^^^^^^^^^^^^^^^^^^^^^^^^^^
  File "C:\Users\91984\AppData\Local\Programs\Python\Python311\Lib\site-packages\rest_framework\viewsets.py", line 125, in view
    return self.dispatch(request, *args, **kwargs)
           ^^^^^^^^^^^^^^^^^^^^^^^^^^^^^^^^^^^^^^^
  File "C:\Users\91984\AppData\Local\Programs\Python\Python311\Lib\site-packages\rest_framework\views.py", line 509, in dispatch
    response = self.handle_exception(exc)
               ^^^^^^^^^^^^^^^^^^^^^^^^^^
  File "C:\Users\91984\AppData\Local\Programs\Python\Python311\Lib\site-packages\rest_framework\views.py", line 469, in handle_exception
    self.raise_uncaught_exception(exc)
  File "C:\Users\91984\AppData\Local\Programs\Python\Python311\Lib\site-packages\rest_framework\views.py", line 480, in raise_uncaught_exception
    raise exc
  File "C:\Users\91984\AppData\Local\Programs\Python\Python311\Lib\site-packages\rest_framework\views.py", line 506, in dispatch
    response = handler(request, *args, **kwargs)
               ^^^^^^^^^^^^^^^^^^^^^^^^^^^^^^^^^
  File "C:\Users\91984\Downloads\CSSS\hardware_monitor_project\hardware_monitor_backend\hardware_api\views.py", line 78, in unresolved
    return Response(serializer.data)
                    ^^^^^^^^^^^^^^^
  File "C:\Users\91984\AppData\Local\Programs\Python\Python311\Lib\site-packages\rest_framework\serializers.py", line 768, in data
    ret = super().data
          ^^^^^^^^^^^^
  File "C:\Users\91984\AppData\Local\Programs\Python\Python311\Lib\site-packages\rest_framework\serializers.py", line 253, in data
    self._data = self.to_representation(self.instance)
                 ^^^^^^^^^^^^^^^^^^^^^^^^^^^^^^^^^^^^^
  File "C:\Users\91984\AppData\Local\Programs\Python\Python311\Lib\site-packages\rest_framework\serializers.py", line 686, in to_representation
    return [
           ^
  File "C:\Users\91984\AppData\Local\Programs\Python\Python311\Lib\site-packages\django\db\models\query.py", line 398, in __iter__
    self._fetch_all()
  File "C:\Users\91984\AppData\Local\Programs\Python\Python311\Lib\site-packages\django\db\models\query.py", line 1881, in _fetch_all
    self._result_cache = list(self._iterable_class(self))
                         ^^^^^^^^^^^^^^^^^^^^^^^^^^^^^^^^
  File "C:\Users\91984\AppData\Local\Programs\Python\Python311\Lib\site-packages\django\db\models\query.py", line 91, in __iter__
    results = compiler.execute_sql(
              ^^^^^^^^^^^^^^^^^^^^^
  File "C:\Users\91984\AppData\Local\Programs\Python\Python311\Lib\site-packages\django\db\models\sql\compiler.py", line 1562, in execute_sql
    cursor.execute(sql, params)
  File "C:\Users\91984\AppData\Local\Programs\Python\Python311\Lib\site-packages\django\db\backends\utils.py", line 102, in execute
    return super().execute(sql, params)
           ^^^^^^^^^^^^^^^^^^^^^^^^^^^^
  File "C:\Users\91984\AppData\Local\Programs\Python\Python311\Lib\site-packages\django\db\backends\utils.py", line 67, in execute
    return self._execute_with_wrappers(
           ^^^^^^^^^^^^^^^^^^^^^^^^^^^^
  File "C:\Users\91984\AppData\Local\Programs\Python\Python311\Lib\site-packages\django\db\backends\utils.py", line 80, in _execute_with_wrappers
    return executor(sql, params, many, context)
           ^^^^^^^^^^^^^^^^^^^^^^^^^^^^^^^^^^^^
  File "C:\Users\91984\AppData\Local\Programs\Python\Python311\Lib\site-packages\django\db\backends\utils.py", line 84, in _execute
    with self.db.wrap_database_errors:
  File "C:\Users\91984\AppData\Local\Programs\Python\Python311\Lib\site-packages\django\db\utils.py", line 91, in __exit__
    raise dj_exc_value.with_traceback(traceback) from exc_value
  File "C:\Users\91984\AppData\Local\Programs\Python\Python311\Lib\site-packages\django\db\backends\utils.py", line 89, in _execute
    return self.cursor.execute(sql, params)
           ^^^^^^^^^^^^^^^^^^^^^^^^^^^^^^^^
  File "C:\Users\91984\AppData\Local\Programs\Python\Python311\Lib\site-packages\django\db\backends\sqlite3\base.py", line 328, in execute
    return super().execute(query, params)
           ^^^^^^^^^^^^^^^^^^^^^^^^^^^^^^
django.db.utils.OperationalError: no such table: hardware_api_hardwareissue
2025-04-01 15:30:16,457 - ERROR - Internal Server Error: /api/dashboard/
Traceback (most recent call last):
  File "C:\Users\91984\AppData\Local\Programs\Python\Python311\Lib\site-packages\django\db\backends\utils.py", line 89, in _execute
    return self.cursor.execute(sql, params)
           ^^^^^^^^^^^^^^^^^^^^^^^^^^^^^^^^
  File "C:\Users\91984\AppData\Local\Programs\Python\Python311\Lib\site-packages\django\db\backends\sqlite3\base.py", line 328, in execute
    return super().execute(query, params)
           ^^^^^^^^^^^^^^^^^^^^^^^^^^^^^^
sqlite3.OperationalError: no such table: hardware_api_systemmetric

The above exception was the direct cause of the following exception:

Traceback (most recent call last):
  File "C:\Users\91984\AppData\Local\Programs\Python\Python311\Lib\site-packages\django\core\handlers\exception.py", line 55, in inner
    response = get_response(request)
               ^^^^^^^^^^^^^^^^^^^^^
  File "C:\Users\91984\AppData\Local\Programs\Python\Python311\Lib\site-packages\django\core\handlers\base.py", line 197, in _get_response
    response = wrapped_callback(request, *callback_args, **callback_kwargs)
               ^^^^^^^^^^^^^^^^^^^^^^^^^^^^^^^^^^^^^^^^^^^^^^^^^^^^^^^^^^^^
  File "C:\Users\91984\AppData\Local\Programs\Python\Python311\Lib\site-packages\django\views\decorators\csrf.py", line 56, in wrapper_view
    return view_func(*args, **kwargs)
           ^^^^^^^^^^^^^^^^^^^^^^^^^^
  File "C:\Users\91984\AppData\Local\Programs\Python\Python311\Lib\site-packages\django\views\generic\base.py", line 104, in view
    return self.dispatch(request, *args, **kwargs)
           ^^^^^^^^^^^^^^^^^^^^^^^^^^^^^^^^^^^^^^^
  File "C:\Users\91984\AppData\Local\Programs\Python\Python311\Lib\site-packages\rest_framework\views.py", line 509, in dispatch
    response = self.handle_exception(exc)
               ^^^^^^^^^^^^^^^^^^^^^^^^^^
  File "C:\Users\91984\AppData\Local\Programs\Python\Python311\Lib\site-packages\rest_framework\views.py", line 469, in handle_exception
    self.raise_uncaught_exception(exc)
  File "C:\Users\91984\AppData\Local\Programs\Python\Python311\Lib\site-packages\rest_framework\views.py", line 480, in raise_uncaught_exception
    raise exc
  File "C:\Users\91984\AppData\Local\Programs\Python\Python311\Lib\site-packages\rest_framework\views.py", line 506, in dispatch
    response = handler(request, *args, **kwargs)
               ^^^^^^^^^^^^^^^^^^^^^^^^^^^^^^^^^
  File "C:\Users\91984\Downloads\CSSS\hardware_monitor_project\hardware_monitor_backend\hardware_api\views.py", line 359, in get
    summary = hardware_monitor.get_system_summary()
              ^^^^^^^^^^^^^^^^^^^^^^^^^^^^^^^^^^^^^
  File "C:\Users\91984\Downloads\CSSS\hardware_monitor_project\hardware_monitor_backend\hardware_api\hardware_monitor.py", line 406, in get_system_summary
    cpu_trend = [m.cpu_percent for m in metrics_history]
                ^^^^^^^^^^^^^^^^^^^^^^^^^^^^^^^^^^^^^^^^
  File "C:\Users\91984\AppData\Local\Programs\Python\Python311\Lib\site-packages\django\db\models\query.py", line 398, in __iter__
    self._fetch_all()
  File "C:\Users\91984\AppData\Local\Programs\Python\Python311\Lib\site-packages\django\db\models\query.py", line 1881, in _fetch_all
    self._result_cache = list(self._iterable_class(self))
                         ^^^^^^^^^^^^^^^^^^^^^^^^^^^^^^^^
  File "C:\Users\91984\AppData\Local\Programs\Python\Python311\Lib\site-packages\django\db\models\query.py", line 91, in __iter__
    results = compiler.execute_sql(
              ^^^^^^^^^^^^^^^^^^^^^
  File "C:\Users\91984\AppData\Local\Programs\Python\Python311\Lib\site-packages\django\db\models\sql\compiler.py", line 1562, in execute_sql
    cursor.execute(sql, params)
  File "C:\Users\91984\AppData\Local\Programs\Python\Python311\Lib\site-packages\django\db\backends\utils.py", line 102, in execute
    return super().execute(sql, params)
           ^^^^^^^^^^^^^^^^^^^^^^^^^^^^
  File "C:\Users\91984\AppData\Local\Programs\Python\Python311\Lib\site-packages\django\db\backends\utils.py", line 67, in execute
    return self._execute_with_wrappers(
           ^^^^^^^^^^^^^^^^^^^^^^^^^^^^
  File "C:\Users\91984\AppData\Local\Programs\Python\Python311\Lib\site-packages\django\db\backends\utils.py", line 80, in _execute_with_wrappers
    return executor(sql, params, many, context)
           ^^^^^^^^^^^^^^^^^^^^^^^^^^^^^^^^^^^^
  File "C:\Users\91984\AppData\Local\Programs\Python\Python311\Lib\site-packages\django\db\backends\utils.py", line 84, in _execute
    with self.db.wrap_database_errors:
  File "C:\Users\91984\AppData\Local\Programs\Python\Python311\Lib\site-packages\django\db\utils.py", line 91, in __exit__
    raise dj_exc_value.with_traceback(traceback) from exc_value
  File "C:\Users\91984\AppData\Local\Programs\Python\Python311\Lib\site-packages\django\db\backends\utils.py", line 89, in _execute
    return self.cursor.execute(sql, params)
           ^^^^^^^^^^^^^^^^^^^^^^^^^^^^^^^^
  File "C:\Users\91984\AppData\Local\Programs\Python\Python311\Lib\site-packages\django\db\backends\sqlite3\base.py", line 328, in execute
    return super().execute(query, params)
           ^^^^^^^^^^^^^^^^^^^^^^^^^^^^^^
django.db.utils.OperationalError: no such table: hardware_api_systemmetric
2025-04-01 15:30:46,385 - ERROR - Internal Server Error: /api/metrics/latest/
Traceback (most recent call last):
  File "C:\Users\91984\AppData\Local\Programs\Python\Python311\Lib\site-packages\django\db\backends\utils.py", line 89, in _execute
    return self.cursor.execute(sql, params)
           ^^^^^^^^^^^^^^^^^^^^^^^^^^^^^^^^
  File "C:\Users\91984\AppData\Local\Programs\Python\Python311\Lib\site-packages\django\db\backends\sqlite3\base.py", line 328, in execute
    return super().execute(query, params)
           ^^^^^^^^^^^^^^^^^^^^^^^^^^^^^^
sqlite3.OperationalError: no such table: hardware_api_systemmetric

The above exception was the direct cause of the following exception:

Traceback (most recent call last):
  File "C:\Users\91984\AppData\Local\Programs\Python\Python311\Lib\site-packages\django\core\handlers\exception.py", line 55, in inner
    response = get_response(request)
               ^^^^^^^^^^^^^^^^^^^^^
  File "C:\Users\91984\AppData\Local\Programs\Python\Python311\Lib\site-packages\django\core\handlers\base.py", line 197, in _get_response
    response = wrapped_callback(request, *callback_args, **callback_kwargs)
               ^^^^^^^^^^^^^^^^^^^^^^^^^^^^^^^^^^^^^^^^^^^^^^^^^^^^^^^^^^^^
  File "C:\Users\91984\AppData\Local\Programs\Python\Python311\Lib\site-packages\django\views\decorators\csrf.py", line 56, in wrapper_view
    return view_func(*args, **kwargs)
           ^^^^^^^^^^^^^^^^^^^^^^^^^^
  File "C:\Users\91984\AppData\Local\Programs\Python\Python311\Lib\site-packages\rest_framework\viewsets.py", line 125, in view
    return self.dispatch(request, *args, **kwargs)
           ^^^^^^^^^^^^^^^^^^^^^^^^^^^^^^^^^^^^^^^
  File "C:\Users\91984\AppData\Local\Programs\Python\Python311\Lib\site-packages\rest_framework\views.py", line 509, in dispatch
    response = self.handle_exception(exc)
               ^^^^^^^^^^^^^^^^^^^^^^^^^^
  File "C:\Users\91984\AppData\Local\Programs\Python\Python311\Lib\site-packages\rest_framework\views.py", line 469, in handle_exception
    self.raise_uncaught_exception(exc)
  File "C:\Users\91984\AppData\Local\Programs\Python\Python311\Lib\site-packages\rest_framework\views.py", line 480, in raise_uncaught_exception
    raise exc
  File "C:\Users\91984\AppData\Local\Programs\Python\Python311\Lib\site-packages\rest_framework\views.py", line 506, in dispatch
    response = handler(request, *args, **kwargs)
               ^^^^^^^^^^^^^^^^^^^^^^^^^^^^^^^^^
  File "C:\Users\91984\Downloads\CSSS\hardware_monitor_project\hardware_monitor_backend\hardware_api\views.py", line 202, in latest
    latest_metric = SystemMetric.objects.order_by('-timestamp').first()
                    ^^^^^^^^^^^^^^^^^^^^^^^^^^^^^^^^^^^^^^^^^^^^^^^^^^^
  File "C:\Users\91984\AppData\Local\Programs\Python\Python311\Lib\site-packages\django\db\models\query.py", line 1057, in first
    for obj in queryset[:1]:
  File "C:\Users\91984\AppData\Local\Programs\Python\Python311\Lib\site-packages\django\db\models\query.py", line 398, in __iter__
    self._fetch_all()
  File "C:\Users\91984\AppData\Local\Programs\Python\Python311\Lib\site-packages\django\db\models\query.py", line 1881, in _fetch_all
    self._result_cache = list(self._iterable_class(self))
                         ^^^^^^^^^^^^^^^^^^^^^^^^^^^^^^^^
  File "C:\Users\91984\AppData\Local\Programs\Python\Python311\Lib\site-packages\django\db\models\query.py", line 91, in __iter__
    results = compiler.execute_sql(
              ^^^^^^^^^^^^^^^^^^^^^
  File "C:\Users\91984\AppData\Local\Programs\Python\Python311\Lib\site-packages\django\db\models\sql\compiler.py", line 1562, in execute_sql
    cursor.execute(sql, params)
  File "C:\Users\91984\AppData\Local\Programs\Python\Python311\Lib\site-packages\django\db\backends\utils.py", line 102, in execute
    return super().execute(sql, params)
           ^^^^^^^^^^^^^^^^^^^^^^^^^^^^
  File "C:\Users\91984\AppData\Local\Programs\Python\Python311\Lib\site-packages\django\db\backends\utils.py", line 67, in execute
    return self._execute_with_wrappers(
           ^^^^^^^^^^^^^^^^^^^^^^^^^^^^
  File "C:\Users\91984\AppData\Local\Programs\Python\Python311\Lib\site-packages\django\db\backends\utils.py", line 80, in _execute_with_wrappers
    return executor(sql, params, many, context)
           ^^^^^^^^^^^^^^^^^^^^^^^^^^^^^^^^^^^^
  File "C:\Users\91984\AppData\Local\Programs\Python\Python311\Lib\site-packages\django\db\backends\utils.py", line 84, in _execute
    with self.db.wrap_database_errors:
  File "C:\Users\91984\AppData\Local\Programs\Python\Python311\Lib\site-packages\django\db\utils.py", line 91, in __exit__
    raise dj_exc_value.with_traceback(traceback) from exc_value
  File "C:\Users\91984\AppData\Local\Programs\Python\Python311\Lib\site-packages\django\db\backends\utils.py", line 89, in _execute
    return self.cursor.execute(sql, params)
           ^^^^^^^^^^^^^^^^^^^^^^^^^^^^^^^^
  File "C:\Users\91984\AppData\Local\Programs\Python\Python311\Lib\site-packages\django\db\backends\sqlite3\base.py", line 328, in execute
    return super().execute(query, params)
           ^^^^^^^^^^^^^^^^^^^^^^^^^^^^^^
django.db.utils.OperationalError: no such table: hardware_api_systemmetric
2025-04-01 15:30:46,523 - ERROR - Internal Server Error: /api/issues/unresolved/
Traceback (most recent call last):
  File "C:\Users\91984\AppData\Local\Programs\Python\Python311\Lib\site-packages\django\db\backends\utils.py", line 89, in _execute
    return self.cursor.execute(sql, params)
           ^^^^^^^^^^^^^^^^^^^^^^^^^^^^^^^^
  File "C:\Users\91984\AppData\Local\Programs\Python\Python311\Lib\site-packages\django\db\backends\sqlite3\base.py", line 328, in execute
    return super().execute(query, params)
           ^^^^^^^^^^^^^^^^^^^^^^^^^^^^^^
sqlite3.OperationalError: no such table: hardware_api_hardwareissue

The above exception was the direct cause of the following exception:

Traceback (most recent call last):
  File "C:\Users\91984\AppData\Local\Programs\Python\Python311\Lib\site-packages\django\core\handlers\exception.py", line 55, in inner
    response = get_response(request)
               ^^^^^^^^^^^^^^^^^^^^^
  File "C:\Users\91984\AppData\Local\Programs\Python\Python311\Lib\site-packages\django\core\handlers\base.py", line 197, in _get_response
    response = wrapped_callback(request, *callback_args, **callback_kwargs)
               ^^^^^^^^^^^^^^^^^^^^^^^^^^^^^^^^^^^^^^^^^^^^^^^^^^^^^^^^^^^^
  File "C:\Users\91984\AppData\Local\Programs\Python\Python311\Lib\site-packages\django\views\decorators\csrf.py", line 56, in wrapper_view
    return view_func(*args, **kwargs)
           ^^^^^^^^^^^^^^^^^^^^^^^^^^
  File "C:\Users\91984\AppData\Local\Programs\Python\Python311\Lib\site-packages\rest_framework\viewsets.py", line 125, in view
    return self.dispatch(request, *args, **kwargs)
           ^^^^^^^^^^^^^^^^^^^^^^^^^^^^^^^^^^^^^^^
  File "C:\Users\91984\AppData\Local\Programs\Python\Python311\Lib\site-packages\rest_framework\views.py", line 509, in dispatch
    response = self.handle_exception(exc)
               ^^^^^^^^^^^^^^^^^^^^^^^^^^
  File "C:\Users\91984\AppData\Local\Programs\Python\Python311\Lib\site-packages\rest_framework\views.py", line 469, in handle_exception
    self.raise_uncaught_exception(exc)
  File "C:\Users\91984\AppData\Local\Programs\Python\Python311\Lib\site-packages\rest_framework\views.py", line 480, in raise_uncaught_exception
    raise exc
  File "C:\Users\91984\AppData\Local\Programs\Python\Python311\Lib\site-packages\rest_framework\views.py", line 506, in dispatch
    response = handler(request, *args, **kwargs)
               ^^^^^^^^^^^^^^^^^^^^^^^^^^^^^^^^^
  File "C:\Users\91984\Downloads\CSSS\hardware_monitor_project\hardware_monitor_backend\hardware_api\views.py", line 78, in unresolved
    return Response(serializer.data)
                    ^^^^^^^^^^^^^^^
  File "C:\Users\91984\AppData\Local\Programs\Python\Python311\Lib\site-packages\rest_framework\serializers.py", line 768, in data
    ret = super().data
          ^^^^^^^^^^^^
  File "C:\Users\91984\AppData\Local\Programs\Python\Python311\Lib\site-packages\rest_framework\serializers.py", line 253, in data
    self._data = self.to_representation(self.instance)
                 ^^^^^^^^^^^^^^^^^^^^^^^^^^^^^^^^^^^^^
  File "C:\Users\91984\AppData\Local\Programs\Python\Python311\Lib\site-packages\rest_framework\serializers.py", line 686, in to_representation
    return [
           ^
  File "C:\Users\91984\AppData\Local\Programs\Python\Python311\Lib\site-packages\django\db\models\query.py", line 398, in __iter__
    self._fetch_all()
  File "C:\Users\91984\AppData\Local\Programs\Python\Python311\Lib\site-packages\django\db\models\query.py", line 1881, in _fetch_all
    self._result_cache = list(self._iterable_class(self))
                         ^^^^^^^^^^^^^^^^^^^^^^^^^^^^^^^^
  File "C:\Users\91984\AppData\Local\Programs\Python\Python311\Lib\site-packages\django\db\models\query.py", line 91, in __iter__
    results = compiler.execute_sql(
              ^^^^^^^^^^^^^^^^^^^^^
  File "C:\Users\91984\AppData\Local\Programs\Python\Python311\Lib\site-packages\django\db\models\sql\compiler.py", line 1562, in execute_sql
    cursor.execute(sql, params)
  File "C:\Users\91984\AppData\Local\Programs\Python\Python311\Lib\site-packages\django\db\backends\utils.py", line 102, in execute
    return super().execute(sql, params)
           ^^^^^^^^^^^^^^^^^^^^^^^^^^^^
  File "C:\Users\91984\AppData\Local\Programs\Python\Python311\Lib\site-packages\django\db\backends\utils.py", line 67, in execute
    return self._execute_with_wrappers(
           ^^^^^^^^^^^^^^^^^^^^^^^^^^^^
  File "C:\Users\91984\AppData\Local\Programs\Python\Python311\Lib\site-packages\django\db\backends\utils.py", line 80, in _execute_with_wrappers
    return executor(sql, params, many, context)
           ^^^^^^^^^^^^^^^^^^^^^^^^^^^^^^^^^^^^
  File "C:\Users\91984\AppData\Local\Programs\Python\Python311\Lib\site-packages\django\db\backends\utils.py", line 84, in _execute
    with self.db.wrap_database_errors:
  File "C:\Users\91984\AppData\Local\Programs\Python\Python311\Lib\site-packages\django\db\utils.py", line 91, in __exit__
    raise dj_exc_value.with_traceback(traceback) from exc_value
  File "C:\Users\91984\AppData\Local\Programs\Python\Python311\Lib\site-packages\django\db\backends\utils.py", line 89, in _execute
    return self.cursor.execute(sql, params)
           ^^^^^^^^^^^^^^^^^^^^^^^^^^^^^^^^
  File "C:\Users\91984\AppData\Local\Programs\Python\Python311\Lib\site-packages\django\db\backends\sqlite3\base.py", line 328, in execute
    return super().execute(query, params)
           ^^^^^^^^^^^^^^^^^^^^^^^^^^^^^^
django.db.utils.OperationalError: no such table: hardware_api_hardwareissue
2025-04-01 15:30:46,591 - ERROR - Internal Server Error: /api/dashboard/
Traceback (most recent call last):
  File "C:\Users\91984\AppData\Local\Programs\Python\Python311\Lib\site-packages\django\db\backends\utils.py", line 89, in _execute
    return self.cursor.execute(sql, params)
           ^^^^^^^^^^^^^^^^^^^^^^^^^^^^^^^^
  File "C:\Users\91984\AppData\Local\Programs\Python\Python311\Lib\site-packages\django\db\backends\sqlite3\base.py", line 328, in execute
    return super().execute(query, params)
           ^^^^^^^^^^^^^^^^^^^^^^^^^^^^^^
sqlite3.OperationalError: no such table: hardware_api_systemmetric

The above exception was the direct cause of the following exception:

Traceback (most recent call last):
  File "C:\Users\91984\AppData\Local\Programs\Python\Python311\Lib\site-packages\django\core\handlers\exception.py", line 55, in inner
    response = get_response(request)
               ^^^^^^^^^^^^^^^^^^^^^
  File "C:\Users\91984\AppData\Local\Programs\Python\Python311\Lib\site-packages\django\core\handlers\base.py", line 197, in _get_response
    response = wrapped_callback(request, *callback_args, **callback_kwargs)
               ^^^^^^^^^^^^^^^^^^^^^^^^^^^^^^^^^^^^^^^^^^^^^^^^^^^^^^^^^^^^
  File "C:\Users\91984\AppData\Local\Programs\Python\Python311\Lib\site-packages\django\views\decorators\csrf.py", line 56, in wrapper_view
    return view_func(*args, **kwargs)
           ^^^^^^^^^^^^^^^^^^^^^^^^^^
  File "C:\Users\91984\AppData\Local\Programs\Python\Python311\Lib\site-packages\django\views\generic\base.py", line 104, in view
    return self.dispatch(request, *args, **kwargs)
           ^^^^^^^^^^^^^^^^^^^^^^^^^^^^^^^^^^^^^^^
  File "C:\Users\91984\AppData\Local\Programs\Python\Python311\Lib\site-packages\rest_framework\views.py", line 509, in dispatch
    response = self.handle_exception(exc)
               ^^^^^^^^^^^^^^^^^^^^^^^^^^
  File "C:\Users\91984\AppData\Local\Programs\Python\Python311\Lib\site-packages\rest_framework\views.py", line 469, in handle_exception
    self.raise_uncaught_exception(exc)
  File "C:\Users\91984\AppData\Local\Programs\Python\Python311\Lib\site-packages\rest_framework\views.py", line 480, in raise_uncaught_exception
    raise exc
  File "C:\Users\91984\AppData\Local\Programs\Python\Python311\Lib\site-packages\rest_framework\views.py", line 506, in dispatch
    response = handler(request, *args, **kwargs)
               ^^^^^^^^^^^^^^^^^^^^^^^^^^^^^^^^^
  File "C:\Users\91984\Downloads\CSSS\hardware_monitor_project\hardware_monitor_backend\hardware_api\views.py", line 359, in get
    summary = hardware_monitor.get_system_summary()
              ^^^^^^^^^^^^^^^^^^^^^^^^^^^^^^^^^^^^^
  File "C:\Users\91984\Downloads\CSSS\hardware_monitor_project\hardware_monitor_backend\hardware_api\hardware_monitor.py", line 406, in get_system_summary
    cpu_trend = [m.cpu_percent for m in metrics_history]
                ^^^^^^^^^^^^^^^^^^^^^^^^^^^^^^^^^^^^^^^^
  File "C:\Users\91984\AppData\Local\Programs\Python\Python311\Lib\site-packages\django\db\models\query.py", line 398, in __iter__
    self._fetch_all()
  File "C:\Users\91984\AppData\Local\Programs\Python\Python311\Lib\site-packages\django\db\models\query.py", line 1881, in _fetch_all
    self._result_cache = list(self._iterable_class(self))
                         ^^^^^^^^^^^^^^^^^^^^^^^^^^^^^^^^
  File "C:\Users\91984\AppData\Local\Programs\Python\Python311\Lib\site-packages\django\db\models\query.py", line 91, in __iter__
    results = compiler.execute_sql(
              ^^^^^^^^^^^^^^^^^^^^^
  File "C:\Users\91984\AppData\Local\Programs\Python\Python311\Lib\site-packages\django\db\models\sql\compiler.py", line 1562, in execute_sql
    cursor.execute(sql, params)
  File "C:\Users\91984\AppData\Local\Programs\Python\Python311\Lib\site-packages\django\db\backends\utils.py", line 102, in execute
    return super().execute(sql, params)
           ^^^^^^^^^^^^^^^^^^^^^^^^^^^^
  File "C:\Users\91984\AppData\Local\Programs\Python\Python311\Lib\site-packages\django\db\backends\utils.py", line 67, in execute
    return self._execute_with_wrappers(
           ^^^^^^^^^^^^^^^^^^^^^^^^^^^^
  File "C:\Users\91984\AppData\Local\Programs\Python\Python311\Lib\site-packages\django\db\backends\utils.py", line 80, in _execute_with_wrappers
    return executor(sql, params, many, context)
           ^^^^^^^^^^^^^^^^^^^^^^^^^^^^^^^^^^^^
  File "C:\Users\91984\AppData\Local\Programs\Python\Python311\Lib\site-packages\django\db\backends\utils.py", line 84, in _execute
    with self.db.wrap_database_errors:
  File "C:\Users\91984\AppData\Local\Programs\Python\Python311\Lib\site-packages\django\db\utils.py", line 91, in __exit__
    raise dj_exc_value.with_traceback(traceback) from exc_value
  File "C:\Users\91984\AppData\Local\Programs\Python\Python311\Lib\site-packages\django\db\backends\utils.py", line 89, in _execute
    return self.cursor.execute(sql, params)
           ^^^^^^^^^^^^^^^^^^^^^^^^^^^^^^^^
  File "C:\Users\91984\AppData\Local\Programs\Python\Python311\Lib\site-packages\django\db\backends\sqlite3\base.py", line 328, in execute
    return super().execute(query, params)
           ^^^^^^^^^^^^^^^^^^^^^^^^^^^^^^
django.db.utils.OperationalError: no such table: hardware_api_systemmetric
2025-04-01 15:31:23,891 - ERROR - Internal Server Error: /api/metrics/latest/
Traceback (most recent call last):
  File "C:\Users\91984\AppData\Local\Programs\Python\Python311\Lib\site-packages\django\db\backends\utils.py", line 89, in _execute
    return self.cursor.execute(sql, params)
           ^^^^^^^^^^^^^^^^^^^^^^^^^^^^^^^^
  File "C:\Users\91984\AppData\Local\Programs\Python\Python311\Lib\site-packages\django\db\backends\sqlite3\base.py", line 328, in execute
    return super().execute(query, params)
           ^^^^^^^^^^^^^^^^^^^^^^^^^^^^^^
sqlite3.OperationalError: no such table: hardware_api_systemmetric

The above exception was the direct cause of the following exception:

Traceback (most recent call last):
  File "C:\Users\91984\AppData\Local\Programs\Python\Python311\Lib\site-packages\django\core\handlers\exception.py", line 55, in inner
    response = get_response(request)
               ^^^^^^^^^^^^^^^^^^^^^
  File "C:\Users\91984\AppData\Local\Programs\Python\Python311\Lib\site-packages\django\core\handlers\base.py", line 197, in _get_response
    response = wrapped_callback(request, *callback_args, **callback_kwargs)
               ^^^^^^^^^^^^^^^^^^^^^^^^^^^^^^^^^^^^^^^^^^^^^^^^^^^^^^^^^^^^
  File "C:\Users\91984\AppData\Local\Programs\Python\Python311\Lib\site-packages\django\views\decorators\csrf.py", line 56, in wrapper_view
    return view_func(*args, **kwargs)
           ^^^^^^^^^^^^^^^^^^^^^^^^^^
  File "C:\Users\91984\AppData\Local\Programs\Python\Python311\Lib\site-packages\rest_framework\viewsets.py", line 125, in view
    return self.dispatch(request, *args, **kwargs)
           ^^^^^^^^^^^^^^^^^^^^^^^^^^^^^^^^^^^^^^^
  File "C:\Users\91984\AppData\Local\Programs\Python\Python311\Lib\site-packages\rest_framework\views.py", line 509, in dispatch
    response = self.handle_exception(exc)
               ^^^^^^^^^^^^^^^^^^^^^^^^^^
  File "C:\Users\91984\AppData\Local\Programs\Python\Python311\Lib\site-packages\rest_framework\views.py", line 469, in handle_exception
    self.raise_uncaught_exception(exc)
  File "C:\Users\91984\AppData\Local\Programs\Python\Python311\Lib\site-packages\rest_framework\views.py", line 480, in raise_uncaught_exception
    raise exc
  File "C:\Users\91984\AppData\Local\Programs\Python\Python311\Lib\site-packages\rest_framework\views.py", line 506, in dispatch
    response = handler(request, *args, **kwargs)
               ^^^^^^^^^^^^^^^^^^^^^^^^^^^^^^^^^
  File "C:\Users\91984\Downloads\CSSS\hardware_monitor_project\hardware_monitor_backend\hardware_api\views.py", line 202, in latest
    latest_metric = SystemMetric.objects.order_by('-timestamp').first()
                    ^^^^^^^^^^^^^^^^^^^^^^^^^^^^^^^^^^^^^^^^^^^^^^^^^^^
  File "C:\Users\91984\AppData\Local\Programs\Python\Python311\Lib\site-packages\django\db\models\query.py", line 1057, in first
    for obj in queryset[:1]:
  File "C:\Users\91984\AppData\Local\Programs\Python\Python311\Lib\site-packages\django\db\models\query.py", line 398, in __iter__
    self._fetch_all()
  File "C:\Users\91984\AppData\Local\Programs\Python\Python311\Lib\site-packages\django\db\models\query.py", line 1881, in _fetch_all
    self._result_cache = list(self._iterable_class(self))
                         ^^^^^^^^^^^^^^^^^^^^^^^^^^^^^^^^
  File "C:\Users\91984\AppData\Local\Programs\Python\Python311\Lib\site-packages\django\db\models\query.py", line 91, in __iter__
    results = compiler.execute_sql(
              ^^^^^^^^^^^^^^^^^^^^^
  File "C:\Users\91984\AppData\Local\Programs\Python\Python311\Lib\site-packages\django\db\models\sql\compiler.py", line 1562, in execute_sql
    cursor.execute(sql, params)
  File "C:\Users\91984\AppData\Local\Programs\Python\Python311\Lib\site-packages\django\db\backends\utils.py", line 102, in execute
    return super().execute(sql, params)
           ^^^^^^^^^^^^^^^^^^^^^^^^^^^^
  File "C:\Users\91984\AppData\Local\Programs\Python\Python311\Lib\site-packages\django\db\backends\utils.py", line 67, in execute
    return self._execute_with_wrappers(
           ^^^^^^^^^^^^^^^^^^^^^^^^^^^^
  File "C:\Users\91984\AppData\Local\Programs\Python\Python311\Lib\site-packages\django\db\backends\utils.py", line 80, in _execute_with_wrappers
    return executor(sql, params, many, context)
           ^^^^^^^^^^^^^^^^^^^^^^^^^^^^^^^^^^^^
  File "C:\Users\91984\AppData\Local\Programs\Python\Python311\Lib\site-packages\django\db\backends\utils.py", line 84, in _execute
    with self.db.wrap_database_errors:
  File "C:\Users\91984\AppData\Local\Programs\Python\Python311\Lib\site-packages\django\db\utils.py", line 91, in __exit__
    raise dj_exc_value.with_traceback(traceback) from exc_value
  File "C:\Users\91984\AppData\Local\Programs\Python\Python311\Lib\site-packages\django\db\backends\utils.py", line 89, in _execute
    return self.cursor.execute(sql, params)
           ^^^^^^^^^^^^^^^^^^^^^^^^^^^^^^^^
  File "C:\Users\91984\AppData\Local\Programs\Python\Python311\Lib\site-packages\django\db\backends\sqlite3\base.py", line 328, in execute
    return super().execute(query, params)
           ^^^^^^^^^^^^^^^^^^^^^^^^^^^^^^
django.db.utils.OperationalError: no such table: hardware_api_systemmetric
2025-04-01 15:31:23,972 - ERROR - Internal Server Error: /api/dashboard/
Traceback (most recent call last):
  File "C:\Users\91984\AppData\Local\Programs\Python\Python311\Lib\site-packages\django\db\backends\utils.py", line 89, in _execute
    return self.cursor.execute(sql, params)
           ^^^^^^^^^^^^^^^^^^^^^^^^^^^^^^^^
  File "C:\Users\91984\AppData\Local\Programs\Python\Python311\Lib\site-packages\django\db\backends\sqlite3\base.py", line 328, in execute
    return super().execute(query, params)
           ^^^^^^^^^^^^^^^^^^^^^^^^^^^^^^
sqlite3.OperationalError: no such table: hardware_api_systemmetric

The above exception was the direct cause of the following exception:

Traceback (most recent call last):
  File "C:\Users\91984\AppData\Local\Programs\Python\Python311\Lib\site-packages\django\core\handlers\exception.py", line 55, in inner
    response = get_response(request)
               ^^^^^^^^^^^^^^^^^^^^^
  File "C:\Users\91984\AppData\Local\Programs\Python\Python311\Lib\site-packages\django\core\handlers\base.py", line 197, in _get_response
    response = wrapped_callback(request, *callback_args, **callback_kwargs)
               ^^^^^^^^^^^^^^^^^^^^^^^^^^^^^^^^^^^^^^^^^^^^^^^^^^^^^^^^^^^^
  File "C:\Users\91984\AppData\Local\Programs\Python\Python311\Lib\site-packages\django\views\decorators\csrf.py", line 56, in wrapper_view
    return view_func(*args, **kwargs)
           ^^^^^^^^^^^^^^^^^^^^^^^^^^
  File "C:\Users\91984\AppData\Local\Programs\Python\Python311\Lib\site-packages\django\views\generic\base.py", line 104, in view
    return self.dispatch(request, *args, **kwargs)
           ^^^^^^^^^^^^^^^^^^^^^^^^^^^^^^^^^^^^^^^
  File "C:\Users\91984\AppData\Local\Programs\Python\Python311\Lib\site-packages\rest_framework\views.py", line 509, in dispatch
    response = self.handle_exception(exc)
               ^^^^^^^^^^^^^^^^^^^^^^^^^^
  File "C:\Users\91984\AppData\Local\Programs\Python\Python311\Lib\site-packages\rest_framework\views.py", line 469, in handle_exception
    self.raise_uncaught_exception(exc)
  File "C:\Users\91984\AppData\Local\Programs\Python\Python311\Lib\site-packages\rest_framework\views.py", line 480, in raise_uncaught_exception
    raise exc
  File "C:\Users\91984\AppData\Local\Programs\Python\Python311\Lib\site-packages\rest_framework\views.py", line 506, in dispatch
    response = handler(request, *args, **kwargs)
               ^^^^^^^^^^^^^^^^^^^^^^^^^^^^^^^^^
  File "C:\Users\91984\Downloads\CSSS\hardware_monitor_project\hardware_monitor_backend\hardware_api\views.py", line 359, in get
    summary = hardware_monitor.get_system_summary()
              ^^^^^^^^^^^^^^^^^^^^^^^^^^^^^^^^^^^^^
  File "C:\Users\91984\Downloads\CSSS\hardware_monitor_project\hardware_monitor_backend\hardware_api\hardware_monitor.py", line 406, in get_system_summary
    cpu_trend = [m.cpu_percent for m in metrics_history]
                ^^^^^^^^^^^^^^^^^^^^^^^^^^^^^^^^^^^^^^^^
  File "C:\Users\91984\AppData\Local\Programs\Python\Python311\Lib\site-packages\django\db\models\query.py", line 398, in __iter__
    self._fetch_all()
  File "C:\Users\91984\AppData\Local\Programs\Python\Python311\Lib\site-packages\django\db\models\query.py", line 1881, in _fetch_all
    self._result_cache = list(self._iterable_class(self))
                         ^^^^^^^^^^^^^^^^^^^^^^^^^^^^^^^^
  File "C:\Users\91984\AppData\Local\Programs\Python\Python311\Lib\site-packages\django\db\models\query.py", line 91, in __iter__
    results = compiler.execute_sql(
              ^^^^^^^^^^^^^^^^^^^^^
  File "C:\Users\91984\AppData\Local\Programs\Python\Python311\Lib\site-packages\django\db\models\sql\compiler.py", line 1562, in execute_sql
    cursor.execute(sql, params)
  File "C:\Users\91984\AppData\Local\Programs\Python\Python311\Lib\site-packages\django\db\backends\utils.py", line 102, in execute
    return super().execute(sql, params)
           ^^^^^^^^^^^^^^^^^^^^^^^^^^^^
  File "C:\Users\91984\AppData\Local\Programs\Python\Python311\Lib\site-packages\django\db\backends\utils.py", line 67, in execute
    return self._execute_with_wrappers(
           ^^^^^^^^^^^^^^^^^^^^^^^^^^^^
  File "C:\Users\91984\AppData\Local\Programs\Python\Python311\Lib\site-packages\django\db\backends\utils.py", line 80, in _execute_with_wrappers
    return executor(sql, params, many, context)
           ^^^^^^^^^^^^^^^^^^^^^^^^^^^^^^^^^^^^
  File "C:\Users\91984\AppData\Local\Programs\Python\Python311\Lib\site-packages\django\db\backends\utils.py", line 84, in _execute
    with self.db.wrap_database_errors:
  File "C:\Users\91984\AppData\Local\Programs\Python\Python311\Lib\site-packages\django\db\utils.py", line 91, in __exit__
    raise dj_exc_value.with_traceback(traceback) from exc_value
  File "C:\Users\91984\AppData\Local\Programs\Python\Python311\Lib\site-packages\django\db\backends\utils.py", line 89, in _execute
    return self.cursor.execute(sql, params)
           ^^^^^^^^^^^^^^^^^^^^^^^^^^^^^^^^
  File "C:\Users\91984\AppData\Local\Programs\Python\Python311\Lib\site-packages\django\db\backends\sqlite3\base.py", line 328, in execute
    return super().execute(query, params)
           ^^^^^^^^^^^^^^^^^^^^^^^^^^^^^^
django.db.utils.OperationalError: no such table: hardware_api_systemmetric
2025-04-01 15:31:24,061 - ERROR - Internal Server Error: /api/issues/unresolved/
Traceback (most recent call last):
  File "C:\Users\91984\AppData\Local\Programs\Python\Python311\Lib\site-packages\django\db\backends\utils.py", line 89, in _execute
    return self.cursor.execute(sql, params)
           ^^^^^^^^^^^^^^^^^^^^^^^^^^^^^^^^
  File "C:\Users\91984\AppData\Local\Programs\Python\Python311\Lib\site-packages\django\db\backends\sqlite3\base.py", line 328, in execute
    return super().execute(query, params)
           ^^^^^^^^^^^^^^^^^^^^^^^^^^^^^^
sqlite3.OperationalError: no such table: hardware_api_hardwareissue

The above exception was the direct cause of the following exception:

Traceback (most recent call last):
  File "C:\Users\91984\AppData\Local\Programs\Python\Python311\Lib\site-packages\django\core\handlers\exception.py", line 55, in inner
    response = get_response(request)
               ^^^^^^^^^^^^^^^^^^^^^
  File "C:\Users\91984\AppData\Local\Programs\Python\Python311\Lib\site-packages\django\core\handlers\base.py", line 197, in _get_response
    response = wrapped_callback(request, *callback_args, **callback_kwargs)
               ^^^^^^^^^^^^^^^^^^^^^^^^^^^^^^^^^^^^^^^^^^^^^^^^^^^^^^^^^^^^
  File "C:\Users\91984\AppData\Local\Programs\Python\Python311\Lib\site-packages\django\views\decorators\csrf.py", line 56, in wrapper_view
    return view_func(*args, **kwargs)
           ^^^^^^^^^^^^^^^^^^^^^^^^^^
  File "C:\Users\91984\AppData\Local\Programs\Python\Python311\Lib\site-packages\rest_framework\viewsets.py", line 125, in view
    return self.dispatch(request, *args, **kwargs)
           ^^^^^^^^^^^^^^^^^^^^^^^^^^^^^^^^^^^^^^^
  File "C:\Users\91984\AppData\Local\Programs\Python\Python311\Lib\site-packages\rest_framework\views.py", line 509, in dispatch
    response = self.handle_exception(exc)
               ^^^^^^^^^^^^^^^^^^^^^^^^^^
  File "C:\Users\91984\AppData\Local\Programs\Python\Python311\Lib\site-packages\rest_framework\views.py", line 469, in handle_exception
    self.raise_uncaught_exception(exc)
  File "C:\Users\91984\AppData\Local\Programs\Python\Python311\Lib\site-packages\rest_framework\views.py", line 480, in raise_uncaught_exception
    raise exc
  File "C:\Users\91984\AppData\Local\Programs\Python\Python311\Lib\site-packages\rest_framework\views.py", line 506, in dispatch
    response = handler(request, *args, **kwargs)
               ^^^^^^^^^^^^^^^^^^^^^^^^^^^^^^^^^
  File "C:\Users\91984\Downloads\CSSS\hardware_monitor_project\hardware_monitor_backend\hardware_api\views.py", line 78, in unresolved
    return Response(serializer.data)
                    ^^^^^^^^^^^^^^^
  File "C:\Users\91984\AppData\Local\Programs\Python\Python311\Lib\site-packages\rest_framework\serializers.py", line 768, in data
    ret = super().data
          ^^^^^^^^^^^^
  File "C:\Users\91984\AppData\Local\Programs\Python\Python311\Lib\site-packages\rest_framework\serializers.py", line 253, in data
    self._data = self.to_representation(self.instance)
                 ^^^^^^^^^^^^^^^^^^^^^^^^^^^^^^^^^^^^^
  File "C:\Users\91984\AppData\Local\Programs\Python\Python311\Lib\site-packages\rest_framework\serializers.py", line 686, in to_representation
    return [
           ^
  File "C:\Users\91984\AppData\Local\Programs\Python\Python311\Lib\site-packages\django\db\models\query.py", line 398, in __iter__
    self._fetch_all()
  File "C:\Users\91984\AppData\Local\Programs\Python\Python311\Lib\site-packages\django\db\models\query.py", line 1881, in _fetch_all
    self._result_cache = list(self._iterable_class(self))
                         ^^^^^^^^^^^^^^^^^^^^^^^^^^^^^^^^
  File "C:\Users\91984\AppData\Local\Programs\Python\Python311\Lib\site-packages\django\db\models\query.py", line 91, in __iter__
    results = compiler.execute_sql(
              ^^^^^^^^^^^^^^^^^^^^^
  File "C:\Users\91984\AppData\Local\Programs\Python\Python311\Lib\site-packages\django\db\models\sql\compiler.py", line 1562, in execute_sql
    cursor.execute(sql, params)
  File "C:\Users\91984\AppData\Local\Programs\Python\Python311\Lib\site-packages\django\db\backends\utils.py", line 102, in execute
    return super().execute(sql, params)
           ^^^^^^^^^^^^^^^^^^^^^^^^^^^^
  File "C:\Users\91984\AppData\Local\Programs\Python\Python311\Lib\site-packages\django\db\backends\utils.py", line 67, in execute
    return self._execute_with_wrappers(
           ^^^^^^^^^^^^^^^^^^^^^^^^^^^^
  File "C:\Users\91984\AppData\Local\Programs\Python\Python311\Lib\site-packages\django\db\backends\utils.py", line 80, in _execute_with_wrappers
    return executor(sql, params, many, context)
           ^^^^^^^^^^^^^^^^^^^^^^^^^^^^^^^^^^^^
  File "C:\Users\91984\AppData\Local\Programs\Python\Python311\Lib\site-packages\django\db\backends\utils.py", line 84, in _execute
    with self.db.wrap_database_errors:
  File "C:\Users\91984\AppData\Local\Programs\Python\Python311\Lib\site-packages\django\db\utils.py", line 91, in __exit__
    raise dj_exc_value.with_traceback(traceback) from exc_value
  File "C:\Users\91984\AppData\Local\Programs\Python\Python311\Lib\site-packages\django\db\backends\utils.py", line 89, in _execute
    return self.cursor.execute(sql, params)
           ^^^^^^^^^^^^^^^^^^^^^^^^^^^^^^^^
  File "C:\Users\91984\AppData\Local\Programs\Python\Python311\Lib\site-packages\django\db\backends\sqlite3\base.py", line 328, in execute
    return super().execute(query, params)
           ^^^^^^^^^^^^^^^^^^^^^^^^^^^^^^
django.db.utils.OperationalError: no such table: hardware_api_hardwareissue
2025-04-01 15:31:40,915 - ERROR - Internal Server Error: /admin/hardware_api/hardwareissue/
Traceback (most recent call last):
  File "C:\Users\91984\AppData\Local\Programs\Python\Python311\Lib\site-packages\django\db\backends\utils.py", line 89, in _execute
    return self.cursor.execute(sql, params)
           ^^^^^^^^^^^^^^^^^^^^^^^^^^^^^^^^
  File "C:\Users\91984\AppData\Local\Programs\Python\Python311\Lib\site-packages\django\db\backends\sqlite3\base.py", line 328, in execute
    return super().execute(query, params)
           ^^^^^^^^^^^^^^^^^^^^^^^^^^^^^^
sqlite3.OperationalError: no such table: hardware_api_hardwareissue

The above exception was the direct cause of the following exception:

Traceback (most recent call last):
  File "C:\Users\91984\AppData\Local\Programs\Python\Python311\Lib\site-packages\django\core\handlers\exception.py", line 55, in inner
    response = get_response(request)
               ^^^^^^^^^^^^^^^^^^^^^
  File "C:\Users\91984\AppData\Local\Programs\Python\Python311\Lib\site-packages\django\core\handlers\base.py", line 197, in _get_response
    response = wrapped_callback(request, *callback_args, **callback_kwargs)
               ^^^^^^^^^^^^^^^^^^^^^^^^^^^^^^^^^^^^^^^^^^^^^^^^^^^^^^^^^^^^
  File "C:\Users\91984\AppData\Local\Programs\Python\Python311\Lib\site-packages\django\contrib\admin\options.py", line 688, in wrapper
    return self.admin_site.admin_view(view)(*args, **kwargs)
           ^^^^^^^^^^^^^^^^^^^^^^^^^^^^^^^^^^^^^^^^^^^^^^^^^
  File "C:\Users\91984\AppData\Local\Programs\Python\Python311\Lib\site-packages\django\utils\decorators.py", line 134, in _wrapper_view
    response = view_func(request, *args, **kwargs)
               ^^^^^^^^^^^^^^^^^^^^^^^^^^^^^^^^^^^
  File "C:\Users\91984\AppData\Local\Programs\Python\Python311\Lib\site-packages\django\views\decorators\cache.py", line 62, in _wrapper_view_func
    response = view_func(request, *args, **kwargs)
               ^^^^^^^^^^^^^^^^^^^^^^^^^^^^^^^^^^^
  File "C:\Users\91984\AppData\Local\Programs\Python\Python311\Lib\site-packages\django\contrib\admin\sites.py", line 242, in inner
    return view(request, *args, **kwargs)
           ^^^^^^^^^^^^^^^^^^^^^^^^^^^^^^
  File "C:\Users\91984\AppData\Local\Programs\Python\Python311\Lib\site-packages\django\utils\decorators.py", line 46, in _wrapper
    return bound_method(*args, **kwargs)
           ^^^^^^^^^^^^^^^^^^^^^^^^^^^^^
  File "C:\Users\91984\AppData\Local\Programs\Python\Python311\Lib\site-packages\django\utils\decorators.py", line 134, in _wrapper_view
    response = view_func(request, *args, **kwargs)
               ^^^^^^^^^^^^^^^^^^^^^^^^^^^^^^^^^^^
  File "C:\Users\91984\AppData\Local\Programs\Python\Python311\Lib\site-packages\django\contrib\admin\options.py", line 1926, in changelist_view
    cl = self.get_changelist_instance(request)
         ^^^^^^^^^^^^^^^^^^^^^^^^^^^^^^^^^^^^^
  File "C:\Users\91984\AppData\Local\Programs\Python\Python311\Lib\site-packages\django\contrib\admin\options.py", line 836, in get_changelist_instance
    return ChangeList(
           ^^^^^^^^^^^
  File "C:\Users\91984\AppData\Local\Programs\Python\Python311\Lib\site-packages\django\contrib\admin\views\main.py", line 123, in __init__
    self.get_results(request)
  File "C:\Users\91984\AppData\Local\Programs\Python\Python311\Lib\site-packages\django\contrib\admin\views\main.py", line 279, in get_results
    result_count = paginator.count
                   ^^^^^^^^^^^^^^^
  File "C:\Users\91984\AppData\Local\Programs\Python\Python311\Lib\site-packages\django\utils\functional.py", line 57, in __get__
    res = instance.__dict__[self.name] = self.func(instance)
                                         ^^^^^^^^^^^^^^^^^^^
  File "C:\Users\91984\AppData\Local\Programs\Python\Python311\Lib\site-packages\django\core\paginator.py", line 93, in count
    return c()
           ^^^
  File "C:\Users\91984\AppData\Local\Programs\Python\Python311\Lib\site-packages\django\db\models\query.py", line 608, in count
    return self.query.get_count(using=self.db)
           ^^^^^^^^^^^^^^^^^^^^^^^^^^^^^^^^^^^
  File "C:\Users\91984\AppData\Local\Programs\Python\Python311\Lib\site-packages\django\db\models\sql\query.py", line 568, in get_count
    return obj.get_aggregation(using, {"__count": Count("*")})["__count"]
           ^^^^^^^^^^^^^^^^^^^^^^^^^^^^^^^^^^^^^^^^^^^^^^^^^^^
  File "C:\Users\91984\AppData\Local\Programs\Python\Python311\Lib\site-packages\django\db\models\sql\query.py", line 554, in get_aggregation
    result = compiler.execute_sql(SINGLE)
             ^^^^^^^^^^^^^^^^^^^^^^^^^^^^
  File "C:\Users\91984\AppData\Local\Programs\Python\Python311\Lib\site-packages\django\db\models\sql\compiler.py", line 1562, in execute_sql
    cursor.execute(sql, params)
  File "C:\Users\91984\AppData\Local\Programs\Python\Python311\Lib\site-packages\django\db\backends\utils.py", line 102, in execute
    return super().execute(sql, params)
           ^^^^^^^^^^^^^^^^^^^^^^^^^^^^
  File "C:\Users\91984\AppData\Local\Programs\Python\Python311\Lib\site-packages\django\db\backends\utils.py", line 67, in execute
    return self._execute_with_wrappers(
           ^^^^^^^^^^^^^^^^^^^^^^^^^^^^
  File "C:\Users\91984\AppData\Local\Programs\Python\Python311\Lib\site-packages\django\db\backends\utils.py", line 80, in _execute_with_wrappers
    return executor(sql, params, many, context)
           ^^^^^^^^^^^^^^^^^^^^^^^^^^^^^^^^^^^^
  File "C:\Users\91984\AppData\Local\Programs\Python\Python311\Lib\site-packages\django\db\backends\utils.py", line 84, in _execute
    with self.db.wrap_database_errors:
  File "C:\Users\91984\AppData\Local\Programs\Python\Python311\Lib\site-packages\django\db\utils.py", line 91, in __exit__
    raise dj_exc_value.with_traceback(traceback) from exc_value
  File "C:\Users\91984\AppData\Local\Programs\Python\Python311\Lib\site-packages\django\db\backends\utils.py", line 89, in _execute
    return self.cursor.execute(sql, params)
           ^^^^^^^^^^^^^^^^^^^^^^^^^^^^^^^^
  File "C:\Users\91984\AppData\Local\Programs\Python\Python311\Lib\site-packages\django\db\backends\sqlite3\base.py", line 328, in execute
    return super().execute(query, params)
           ^^^^^^^^^^^^^^^^^^^^^^^^^^^^^^
django.db.utils.OperationalError: no such table: hardware_api_hardwareissue
2025-04-01 15:31:46,506 - ERROR - Internal Server Error: /api/metrics/latest/
Traceback (most recent call last):
  File "C:\Users\91984\AppData\Local\Programs\Python\Python311\Lib\site-packages\django\db\backends\utils.py", line 89, in _execute
    return self.cursor.execute(sql, params)
           ^^^^^^^^^^^^^^^^^^^^^^^^^^^^^^^^
  File "C:\Users\91984\AppData\Local\Programs\Python\Python311\Lib\site-packages\django\db\backends\sqlite3\base.py", line 328, in execute
    return super().execute(query, params)
           ^^^^^^^^^^^^^^^^^^^^^^^^^^^^^^
sqlite3.OperationalError: no such table: hardware_api_systemmetric

The above exception was the direct cause of the following exception:

Traceback (most recent call last):
  File "C:\Users\91984\AppData\Local\Programs\Python\Python311\Lib\site-packages\django\core\handlers\exception.py", line 55, in inner
    response = get_response(request)
               ^^^^^^^^^^^^^^^^^^^^^
  File "C:\Users\91984\AppData\Local\Programs\Python\Python311\Lib\site-packages\django\core\handlers\base.py", line 197, in _get_response
    response = wrapped_callback(request, *callback_args, **callback_kwargs)
               ^^^^^^^^^^^^^^^^^^^^^^^^^^^^^^^^^^^^^^^^^^^^^^^^^^^^^^^^^^^^
  File "C:\Users\91984\AppData\Local\Programs\Python\Python311\Lib\site-packages\django\views\decorators\csrf.py", line 56, in wrapper_view
    return view_func(*args, **kwargs)
           ^^^^^^^^^^^^^^^^^^^^^^^^^^
  File "C:\Users\91984\AppData\Local\Programs\Python\Python311\Lib\site-packages\rest_framework\viewsets.py", line 125, in view
    return self.dispatch(request, *args, **kwargs)
           ^^^^^^^^^^^^^^^^^^^^^^^^^^^^^^^^^^^^^^^
  File "C:\Users\91984\AppData\Local\Programs\Python\Python311\Lib\site-packages\rest_framework\views.py", line 509, in dispatch
    response = self.handle_exception(exc)
               ^^^^^^^^^^^^^^^^^^^^^^^^^^
  File "C:\Users\91984\AppData\Local\Programs\Python\Python311\Lib\site-packages\rest_framework\views.py", line 469, in handle_exception
    self.raise_uncaught_exception(exc)
  File "C:\Users\91984\AppData\Local\Programs\Python\Python311\Lib\site-packages\rest_framework\views.py", line 480, in raise_uncaught_exception
    raise exc
  File "C:\Users\91984\AppData\Local\Programs\Python\Python311\Lib\site-packages\rest_framework\views.py", line 506, in dispatch
    response = handler(request, *args, **kwargs)
               ^^^^^^^^^^^^^^^^^^^^^^^^^^^^^^^^^
  File "C:\Users\91984\Downloads\CSSS\hardware_monitor_project\hardware_monitor_backend\hardware_api\views.py", line 202, in latest
    latest_metric = SystemMetric.objects.order_by('-timestamp').first()
                    ^^^^^^^^^^^^^^^^^^^^^^^^^^^^^^^^^^^^^^^^^^^^^^^^^^^
  File "C:\Users\91984\AppData\Local\Programs\Python\Python311\Lib\site-packages\django\db\models\query.py", line 1057, in first
    for obj in queryset[:1]:
  File "C:\Users\91984\AppData\Local\Programs\Python\Python311\Lib\site-packages\django\db\models\query.py", line 398, in __iter__
    self._fetch_all()
  File "C:\Users\91984\AppData\Local\Programs\Python\Python311\Lib\site-packages\django\db\models\query.py", line 1881, in _fetch_all
    self._result_cache = list(self._iterable_class(self))
                         ^^^^^^^^^^^^^^^^^^^^^^^^^^^^^^^^
  File "C:\Users\91984\AppData\Local\Programs\Python\Python311\Lib\site-packages\django\db\models\query.py", line 91, in __iter__
    results = compiler.execute_sql(
              ^^^^^^^^^^^^^^^^^^^^^
  File "C:\Users\91984\AppData\Local\Programs\Python\Python311\Lib\site-packages\django\db\models\sql\compiler.py", line 1562, in execute_sql
    cursor.execute(sql, params)
  File "C:\Users\91984\AppData\Local\Programs\Python\Python311\Lib\site-packages\django\db\backends\utils.py", line 102, in execute
    return super().execute(sql, params)
           ^^^^^^^^^^^^^^^^^^^^^^^^^^^^
  File "C:\Users\91984\AppData\Local\Programs\Python\Python311\Lib\site-packages\django\db\backends\utils.py", line 67, in execute
    return self._execute_with_wrappers(
           ^^^^^^^^^^^^^^^^^^^^^^^^^^^^
  File "C:\Users\91984\AppData\Local\Programs\Python\Python311\Lib\site-packages\django\db\backends\utils.py", line 80, in _execute_with_wrappers
    return executor(sql, params, many, context)
           ^^^^^^^^^^^^^^^^^^^^^^^^^^^^^^^^^^^^
  File "C:\Users\91984\AppData\Local\Programs\Python\Python311\Lib\site-packages\django\db\backends\utils.py", line 84, in _execute
    with self.db.wrap_database_errors:
  File "C:\Users\91984\AppData\Local\Programs\Python\Python311\Lib\site-packages\django\db\utils.py", line 91, in __exit__
    raise dj_exc_value.with_traceback(traceback) from exc_value
  File "C:\Users\91984\AppData\Local\Programs\Python\Python311\Lib\site-packages\django\db\backends\utils.py", line 89, in _execute
    return self.cursor.execute(sql, params)
           ^^^^^^^^^^^^^^^^^^^^^^^^^^^^^^^^
  File "C:\Users\91984\AppData\Local\Programs\Python\Python311\Lib\site-packages\django\db\backends\sqlite3\base.py", line 328, in execute
    return super().execute(query, params)
           ^^^^^^^^^^^^^^^^^^^^^^^^^^^^^^
django.db.utils.OperationalError: no such table: hardware_api_systemmetric
2025-04-01 15:31:46,654 - ERROR - Internal Server Error: /api/issues/unresolved/
Traceback (most recent call last):
  File "C:\Users\91984\AppData\Local\Programs\Python\Python311\Lib\site-packages\django\db\backends\utils.py", line 89, in _execute
    return self.cursor.execute(sql, params)
           ^^^^^^^^^^^^^^^^^^^^^^^^^^^^^^^^
  File "C:\Users\91984\AppData\Local\Programs\Python\Python311\Lib\site-packages\django\db\backends\sqlite3\base.py", line 328, in execute
    return super().execute(query, params)
           ^^^^^^^^^^^^^^^^^^^^^^^^^^^^^^
sqlite3.OperationalError: no such table: hardware_api_hardwareissue

The above exception was the direct cause of the following exception:

Traceback (most recent call last):
  File "C:\Users\91984\AppData\Local\Programs\Python\Python311\Lib\site-packages\django\core\handlers\exception.py", line 55, in inner
    response = get_response(request)
               ^^^^^^^^^^^^^^^^^^^^^
  File "C:\Users\91984\AppData\Local\Programs\Python\Python311\Lib\site-packages\django\core\handlers\base.py", line 197, in _get_response
    response = wrapped_callback(request, *callback_args, **callback_kwargs)
               ^^^^^^^^^^^^^^^^^^^^^^^^^^^^^^^^^^^^^^^^^^^^^^^^^^^^^^^^^^^^
  File "C:\Users\91984\AppData\Local\Programs\Python\Python311\Lib\site-packages\django\views\decorators\csrf.py", line 56, in wrapper_view
    return view_func(*args, **kwargs)
           ^^^^^^^^^^^^^^^^^^^^^^^^^^
  File "C:\Users\91984\AppData\Local\Programs\Python\Python311\Lib\site-packages\rest_framework\viewsets.py", line 125, in view
    return self.dispatch(request, *args, **kwargs)
           ^^^^^^^^^^^^^^^^^^^^^^^^^^^^^^^^^^^^^^^
  File "C:\Users\91984\AppData\Local\Programs\Python\Python311\Lib\site-packages\rest_framework\views.py", line 509, in dispatch
    response = self.handle_exception(exc)
               ^^^^^^^^^^^^^^^^^^^^^^^^^^
  File "C:\Users\91984\AppData\Local\Programs\Python\Python311\Lib\site-packages\rest_framework\views.py", line 469, in handle_exception
    self.raise_uncaught_exception(exc)
  File "C:\Users\91984\AppData\Local\Programs\Python\Python311\Lib\site-packages\rest_framework\views.py", line 480, in raise_uncaught_exception
    raise exc
  File "C:\Users\91984\AppData\Local\Programs\Python\Python311\Lib\site-packages\rest_framework\views.py", line 506, in dispatch
    response = handler(request, *args, **kwargs)
               ^^^^^^^^^^^^^^^^^^^^^^^^^^^^^^^^^
  File "C:\Users\91984\Downloads\CSSS\hardware_monitor_project\hardware_monitor_backend\hardware_api\views.py", line 78, in unresolved
    return Response(serializer.data)
                    ^^^^^^^^^^^^^^^
  File "C:\Users\91984\AppData\Local\Programs\Python\Python311\Lib\site-packages\rest_framework\serializers.py", line 768, in data
    ret = super().data
          ^^^^^^^^^^^^
  File "C:\Users\91984\AppData\Local\Programs\Python\Python311\Lib\site-packages\rest_framework\serializers.py", line 253, in data
    self._data = self.to_representation(self.instance)
                 ^^^^^^^^^^^^^^^^^^^^^^^^^^^^^^^^^^^^^
  File "C:\Users\91984\AppData\Local\Programs\Python\Python311\Lib\site-packages\rest_framework\serializers.py", line 686, in to_representation
    return [
           ^
  File "C:\Users\91984\AppData\Local\Programs\Python\Python311\Lib\site-packages\django\db\models\query.py", line 398, in __iter__
    self._fetch_all()
  File "C:\Users\91984\AppData\Local\Programs\Python\Python311\Lib\site-packages\django\db\models\query.py", line 1881, in _fetch_all
    self._result_cache = list(self._iterable_class(self))
                         ^^^^^^^^^^^^^^^^^^^^^^^^^^^^^^^^
  File "C:\Users\91984\AppData\Local\Programs\Python\Python311\Lib\site-packages\django\db\models\query.py", line 91, in __iter__
    results = compiler.execute_sql(
              ^^^^^^^^^^^^^^^^^^^^^
  File "C:\Users\91984\AppData\Local\Programs\Python\Python311\Lib\site-packages\django\db\models\sql\compiler.py", line 1562, in execute_sql
    cursor.execute(sql, params)
  File "C:\Users\91984\AppData\Local\Programs\Python\Python311\Lib\site-packages\django\db\backends\utils.py", line 102, in execute
    return super().execute(sql, params)
           ^^^^^^^^^^^^^^^^^^^^^^^^^^^^
  File "C:\Users\91984\AppData\Local\Programs\Python\Python311\Lib\site-packages\django\db\backends\utils.py", line 67, in execute
    return self._execute_with_wrappers(
           ^^^^^^^^^^^^^^^^^^^^^^^^^^^^
  File "C:\Users\91984\AppData\Local\Programs\Python\Python311\Lib\site-packages\django\db\backends\utils.py", line 80, in _execute_with_wrappers
    return executor(sql, params, many, context)
           ^^^^^^^^^^^^^^^^^^^^^^^^^^^^^^^^^^^^
  File "C:\Users\91984\AppData\Local\Programs\Python\Python311\Lib\site-packages\django\db\backends\utils.py", line 84, in _execute
    with self.db.wrap_database_errors:
  File "C:\Users\91984\AppData\Local\Programs\Python\Python311\Lib\site-packages\django\db\utils.py", line 91, in __exit__
    raise dj_exc_value.with_traceback(traceback) from exc_value
  File "C:\Users\91984\AppData\Local\Programs\Python\Python311\Lib\site-packages\django\db\backends\utils.py", line 89, in _execute
    return self.cursor.execute(sql, params)
           ^^^^^^^^^^^^^^^^^^^^^^^^^^^^^^^^
  File "C:\Users\91984\AppData\Local\Programs\Python\Python311\Lib\site-packages\django\db\backends\sqlite3\base.py", line 328, in execute
    return super().execute(query, params)
           ^^^^^^^^^^^^^^^^^^^^^^^^^^^^^^
django.db.utils.OperationalError: no such table: hardware_api_hardwareissue
2025-04-01 15:31:46,769 - ERROR - Internal Server Error: /api/dashboard/
Traceback (most recent call last):
  File "C:\Users\91984\AppData\Local\Programs\Python\Python311\Lib\site-packages\django\db\backends\utils.py", line 89, in _execute
    return self.cursor.execute(sql, params)
           ^^^^^^^^^^^^^^^^^^^^^^^^^^^^^^^^
  File "C:\Users\91984\AppData\Local\Programs\Python\Python311\Lib\site-packages\django\db\backends\sqlite3\base.py", line 328, in execute
    return super().execute(query, params)
           ^^^^^^^^^^^^^^^^^^^^^^^^^^^^^^
sqlite3.OperationalError: no such table: hardware_api_systemmetric

The above exception was the direct cause of the following exception:

Traceback (most recent call last):
  File "C:\Users\91984\AppData\Local\Programs\Python\Python311\Lib\site-packages\django\core\handlers\exception.py", line 55, in inner
    response = get_response(request)
               ^^^^^^^^^^^^^^^^^^^^^
  File "C:\Users\91984\AppData\Local\Programs\Python\Python311\Lib\site-packages\django\core\handlers\base.py", line 197, in _get_response
    response = wrapped_callback(request, *callback_args, **callback_kwargs)
               ^^^^^^^^^^^^^^^^^^^^^^^^^^^^^^^^^^^^^^^^^^^^^^^^^^^^^^^^^^^^
  File "C:\Users\91984\AppData\Local\Programs\Python\Python311\Lib\site-packages\django\views\decorators\csrf.py", line 56, in wrapper_view
    return view_func(*args, **kwargs)
           ^^^^^^^^^^^^^^^^^^^^^^^^^^
  File "C:\Users\91984\AppData\Local\Programs\Python\Python311\Lib\site-packages\django\views\generic\base.py", line 104, in view
    return self.dispatch(request, *args, **kwargs)
           ^^^^^^^^^^^^^^^^^^^^^^^^^^^^^^^^^^^^^^^
  File "C:\Users\91984\AppData\Local\Programs\Python\Python311\Lib\site-packages\rest_framework\views.py", line 509, in dispatch
    response = self.handle_exception(exc)
               ^^^^^^^^^^^^^^^^^^^^^^^^^^
  File "C:\Users\91984\AppData\Local\Programs\Python\Python311\Lib\site-packages\rest_framework\views.py", line 469, in handle_exception
    self.raise_uncaught_exception(exc)
  File "C:\Users\91984\AppData\Local\Programs\Python\Python311\Lib\site-packages\rest_framework\views.py", line 480, in raise_uncaught_exception
    raise exc
  File "C:\Users\91984\AppData\Local\Programs\Python\Python311\Lib\site-packages\rest_framework\views.py", line 506, in dispatch
    response = handler(request, *args, **kwargs)
               ^^^^^^^^^^^^^^^^^^^^^^^^^^^^^^^^^
  File "C:\Users\91984\Downloads\CSSS\hardware_monitor_project\hardware_monitor_backend\hardware_api\views.py", line 359, in get
    summary = hardware_monitor.get_system_summary()
              ^^^^^^^^^^^^^^^^^^^^^^^^^^^^^^^^^^^^^
  File "C:\Users\91984\Downloads\CSSS\hardware_monitor_project\hardware_monitor_backend\hardware_api\hardware_monitor.py", line 406, in get_system_summary
    cpu_trend = [m.cpu_percent for m in metrics_history]
                ^^^^^^^^^^^^^^^^^^^^^^^^^^^^^^^^^^^^^^^^
  File "C:\Users\91984\AppData\Local\Programs\Python\Python311\Lib\site-packages\django\db\models\query.py", line 398, in __iter__
    self._fetch_all()
  File "C:\Users\91984\AppData\Local\Programs\Python\Python311\Lib\site-packages\django\db\models\query.py", line 1881, in _fetch_all
    self._result_cache = list(self._iterable_class(self))
                         ^^^^^^^^^^^^^^^^^^^^^^^^^^^^^^^^
  File "C:\Users\91984\AppData\Local\Programs\Python\Python311\Lib\site-packages\django\db\models\query.py", line 91, in __iter__
    results = compiler.execute_sql(
              ^^^^^^^^^^^^^^^^^^^^^
  File "C:\Users\91984\AppData\Local\Programs\Python\Python311\Lib\site-packages\django\db\models\sql\compiler.py", line 1562, in execute_sql
    cursor.execute(sql, params)
  File "C:\Users\91984\AppData\Local\Programs\Python\Python311\Lib\site-packages\django\db\backends\utils.py", line 102, in execute
    return super().execute(sql, params)
           ^^^^^^^^^^^^^^^^^^^^^^^^^^^^
  File "C:\Users\91984\AppData\Local\Programs\Python\Python311\Lib\site-packages\django\db\backends\utils.py", line 67, in execute
    return self._execute_with_wrappers(
           ^^^^^^^^^^^^^^^^^^^^^^^^^^^^
  File "C:\Users\91984\AppData\Local\Programs\Python\Python311\Lib\site-packages\django\db\backends\utils.py", line 80, in _execute_with_wrappers
    return executor(sql, params, many, context)
           ^^^^^^^^^^^^^^^^^^^^^^^^^^^^^^^^^^^^
  File "C:\Users\91984\AppData\Local\Programs\Python\Python311\Lib\site-packages\django\db\backends\utils.py", line 84, in _execute
    with self.db.wrap_database_errors:
  File "C:\Users\91984\AppData\Local\Programs\Python\Python311\Lib\site-packages\django\db\utils.py", line 91, in __exit__
    raise dj_exc_value.with_traceback(traceback) from exc_value
  File "C:\Users\91984\AppData\Local\Programs\Python\Python311\Lib\site-packages\django\db\backends\utils.py", line 89, in _execute
    return self.cursor.execute(sql, params)
           ^^^^^^^^^^^^^^^^^^^^^^^^^^^^^^^^
  File "C:\Users\91984\AppData\Local\Programs\Python\Python311\Lib\site-packages\django\db\backends\sqlite3\base.py", line 328, in execute
    return super().execute(query, params)
           ^^^^^^^^^^^^^^^^^^^^^^^^^^^^^^
django.db.utils.OperationalError: no such table: hardware_api_systemmetric
2025-04-01 15:31:48,024 - ERROR - Internal Server Error: /admin/hardware_api/modeltraininghistory/
Traceback (most recent call last):
  File "C:\Users\91984\AppData\Local\Programs\Python\Python311\Lib\site-packages\django\db\backends\utils.py", line 89, in _execute
    return self.cursor.execute(sql, params)
           ^^^^^^^^^^^^^^^^^^^^^^^^^^^^^^^^
  File "C:\Users\91984\AppData\Local\Programs\Python\Python311\Lib\site-packages\django\db\backends\sqlite3\base.py", line 328, in execute
    return super().execute(query, params)
           ^^^^^^^^^^^^^^^^^^^^^^^^^^^^^^
sqlite3.OperationalError: no such table: hardware_api_modeltraininghistory

The above exception was the direct cause of the following exception:

Traceback (most recent call last):
  File "C:\Users\91984\AppData\Local\Programs\Python\Python311\Lib\site-packages\django\core\handlers\exception.py", line 55, in inner
    response = get_response(request)
               ^^^^^^^^^^^^^^^^^^^^^
  File "C:\Users\91984\AppData\Local\Programs\Python\Python311\Lib\site-packages\django\core\handlers\base.py", line 197, in _get_response
    response = wrapped_callback(request, *callback_args, **callback_kwargs)
               ^^^^^^^^^^^^^^^^^^^^^^^^^^^^^^^^^^^^^^^^^^^^^^^^^^^^^^^^^^^^
  File "C:\Users\91984\AppData\Local\Programs\Python\Python311\Lib\site-packages\django\contrib\admin\options.py", line 688, in wrapper
    return self.admin_site.admin_view(view)(*args, **kwargs)
           ^^^^^^^^^^^^^^^^^^^^^^^^^^^^^^^^^^^^^^^^^^^^^^^^^
  File "C:\Users\91984\AppData\Local\Programs\Python\Python311\Lib\site-packages\django\utils\decorators.py", line 134, in _wrapper_view
    response = view_func(request, *args, **kwargs)
               ^^^^^^^^^^^^^^^^^^^^^^^^^^^^^^^^^^^
  File "C:\Users\91984\AppData\Local\Programs\Python\Python311\Lib\site-packages\django\views\decorators\cache.py", line 62, in _wrapper_view_func
    response = view_func(request, *args, **kwargs)
               ^^^^^^^^^^^^^^^^^^^^^^^^^^^^^^^^^^^
  File "C:\Users\91984\AppData\Local\Programs\Python\Python311\Lib\site-packages\django\contrib\admin\sites.py", line 242, in inner
    return view(request, *args, **kwargs)
           ^^^^^^^^^^^^^^^^^^^^^^^^^^^^^^
  File "C:\Users\91984\AppData\Local\Programs\Python\Python311\Lib\site-packages\django\utils\decorators.py", line 46, in _wrapper
    return bound_method(*args, **kwargs)
           ^^^^^^^^^^^^^^^^^^^^^^^^^^^^^
  File "C:\Users\91984\AppData\Local\Programs\Python\Python311\Lib\site-packages\django\utils\decorators.py", line 134, in _wrapper_view
    response = view_func(request, *args, **kwargs)
               ^^^^^^^^^^^^^^^^^^^^^^^^^^^^^^^^^^^
  File "C:\Users\91984\AppData\Local\Programs\Python\Python311\Lib\site-packages\django\contrib\admin\options.py", line 1926, in changelist_view
    cl = self.get_changelist_instance(request)
         ^^^^^^^^^^^^^^^^^^^^^^^^^^^^^^^^^^^^^
  File "C:\Users\91984\AppData\Local\Programs\Python\Python311\Lib\site-packages\django\contrib\admin\options.py", line 836, in get_changelist_instance
    return ChangeList(
           ^^^^^^^^^^^
  File "C:\Users\91984\AppData\Local\Programs\Python\Python311\Lib\site-packages\django\contrib\admin\views\main.py", line 123, in __init__
    self.get_results(request)
  File "C:\Users\91984\AppData\Local\Programs\Python\Python311\Lib\site-packages\django\contrib\admin\views\main.py", line 279, in get_results
    result_count = paginator.count
                   ^^^^^^^^^^^^^^^
  File "C:\Users\91984\AppData\Local\Programs\Python\Python311\Lib\site-packages\django\utils\functional.py", line 57, in __get__
    res = instance.__dict__[self.name] = self.func(instance)
                                         ^^^^^^^^^^^^^^^^^^^
  File "C:\Users\91984\AppData\Local\Programs\Python\Python311\Lib\site-packages\django\core\paginator.py", line 93, in count
    return c()
           ^^^
  File "C:\Users\91984\AppData\Local\Programs\Python\Python311\Lib\site-packages\django\db\models\query.py", line 608, in count
    return self.query.get_count(using=self.db)
           ^^^^^^^^^^^^^^^^^^^^^^^^^^^^^^^^^^^
  File "C:\Users\91984\AppData\Local\Programs\Python\Python311\Lib\site-packages\django\db\models\sql\query.py", line 568, in get_count
    return obj.get_aggregation(using, {"__count": Count("*")})["__count"]
           ^^^^^^^^^^^^^^^^^^^^^^^^^^^^^^^^^^^^^^^^^^^^^^^^^^^
  File "C:\Users\91984\AppData\Local\Programs\Python\Python311\Lib\site-packages\django\db\models\sql\query.py", line 554, in get_aggregation
    result = compiler.execute_sql(SINGLE)
             ^^^^^^^^^^^^^^^^^^^^^^^^^^^^
  File "C:\Users\91984\AppData\Local\Programs\Python\Python311\Lib\site-packages\django\db\models\sql\compiler.py", line 1562, in execute_sql
    cursor.execute(sql, params)
  File "C:\Users\91984\AppData\Local\Programs\Python\Python311\Lib\site-packages\django\db\backends\utils.py", line 102, in execute
    return super().execute(sql, params)
           ^^^^^^^^^^^^^^^^^^^^^^^^^^^^
  File "C:\Users\91984\AppData\Local\Programs\Python\Python311\Lib\site-packages\django\db\backends\utils.py", line 67, in execute
    return self._execute_with_wrappers(
           ^^^^^^^^^^^^^^^^^^^^^^^^^^^^
  File "C:\Users\91984\AppData\Local\Programs\Python\Python311\Lib\site-packages\django\db\backends\utils.py", line 80, in _execute_with_wrappers
    return executor(sql, params, many, context)
           ^^^^^^^^^^^^^^^^^^^^^^^^^^^^^^^^^^^^
  File "C:\Users\91984\AppData\Local\Programs\Python\Python311\Lib\site-packages\django\db\backends\utils.py", line 84, in _execute
    with self.db.wrap_database_errors:
  File "C:\Users\91984\AppData\Local\Programs\Python\Python311\Lib\site-packages\django\db\utils.py", line 91, in __exit__
    raise dj_exc_value.with_traceback(traceback) from exc_value
  File "C:\Users\91984\AppData\Local\Programs\Python\Python311\Lib\site-packages\django\db\backends\utils.py", line 89, in _execute
    return self.cursor.execute(sql, params)
           ^^^^^^^^^^^^^^^^^^^^^^^^^^^^^^^^
  File "C:\Users\91984\AppData\Local\Programs\Python\Python311\Lib\site-packages\django\db\backends\sqlite3\base.py", line 328, in execute
    return super().execute(query, params)
           ^^^^^^^^^^^^^^^^^^^^^^^^^^^^^^
django.db.utils.OperationalError: no such table: hardware_api_modeltraininghistory
2025-04-01 15:31:51,531 - ERROR - Internal Server Error: /admin/hardware_api/systemmetric/
Traceback (most recent call last):
  File "C:\Users\91984\AppData\Local\Programs\Python\Python311\Lib\site-packages\django\db\backends\utils.py", line 89, in _execute
    return self.cursor.execute(sql, params)
           ^^^^^^^^^^^^^^^^^^^^^^^^^^^^^^^^
  File "C:\Users\91984\AppData\Local\Programs\Python\Python311\Lib\site-packages\django\db\backends\sqlite3\base.py", line 328, in execute
    return super().execute(query, params)
           ^^^^^^^^^^^^^^^^^^^^^^^^^^^^^^
sqlite3.OperationalError: no such table: hardware_api_systemmetric

The above exception was the direct cause of the following exception:

Traceback (most recent call last):
  File "C:\Users\91984\AppData\Local\Programs\Python\Python311\Lib\site-packages\django\core\handlers\exception.py", line 55, in inner
    response = get_response(request)
               ^^^^^^^^^^^^^^^^^^^^^
  File "C:\Users\91984\AppData\Local\Programs\Python\Python311\Lib\site-packages\django\core\handlers\base.py", line 197, in _get_response
    response = wrapped_callback(request, *callback_args, **callback_kwargs)
               ^^^^^^^^^^^^^^^^^^^^^^^^^^^^^^^^^^^^^^^^^^^^^^^^^^^^^^^^^^^^
  File "C:\Users\91984\AppData\Local\Programs\Python\Python311\Lib\site-packages\django\contrib\admin\options.py", line 688, in wrapper
    return self.admin_site.admin_view(view)(*args, **kwargs)
           ^^^^^^^^^^^^^^^^^^^^^^^^^^^^^^^^^^^^^^^^^^^^^^^^^
  File "C:\Users\91984\AppData\Local\Programs\Python\Python311\Lib\site-packages\django\utils\decorators.py", line 134, in _wrapper_view
    response = view_func(request, *args, **kwargs)
               ^^^^^^^^^^^^^^^^^^^^^^^^^^^^^^^^^^^
  File "C:\Users\91984\AppData\Local\Programs\Python\Python311\Lib\site-packages\django\views\decorators\cache.py", line 62, in _wrapper_view_func
    response = view_func(request, *args, **kwargs)
               ^^^^^^^^^^^^^^^^^^^^^^^^^^^^^^^^^^^
  File "C:\Users\91984\AppData\Local\Programs\Python\Python311\Lib\site-packages\django\contrib\admin\sites.py", line 242, in inner
    return view(request, *args, **kwargs)
           ^^^^^^^^^^^^^^^^^^^^^^^^^^^^^^
  File "C:\Users\91984\AppData\Local\Programs\Python\Python311\Lib\site-packages\django\utils\decorators.py", line 46, in _wrapper
    return bound_method(*args, **kwargs)
           ^^^^^^^^^^^^^^^^^^^^^^^^^^^^^
  File "C:\Users\91984\AppData\Local\Programs\Python\Python311\Lib\site-packages\django\utils\decorators.py", line 134, in _wrapper_view
    response = view_func(request, *args, **kwargs)
               ^^^^^^^^^^^^^^^^^^^^^^^^^^^^^^^^^^^
  File "C:\Users\91984\AppData\Local\Programs\Python\Python311\Lib\site-packages\django\contrib\admin\options.py", line 1926, in changelist_view
    cl = self.get_changelist_instance(request)
         ^^^^^^^^^^^^^^^^^^^^^^^^^^^^^^^^^^^^^
  File "C:\Users\91984\AppData\Local\Programs\Python\Python311\Lib\site-packages\django\contrib\admin\options.py", line 836, in get_changelist_instance
    return ChangeList(
           ^^^^^^^^^^^
  File "C:\Users\91984\AppData\Local\Programs\Python\Python311\Lib\site-packages\django\contrib\admin\views\main.py", line 123, in __init__
    self.get_results(request)
  File "C:\Users\91984\AppData\Local\Programs\Python\Python311\Lib\site-packages\django\contrib\admin\views\main.py", line 279, in get_results
    result_count = paginator.count
                   ^^^^^^^^^^^^^^^
  File "C:\Users\91984\AppData\Local\Programs\Python\Python311\Lib\site-packages\django\utils\functional.py", line 57, in __get__
    res = instance.__dict__[self.name] = self.func(instance)
                                         ^^^^^^^^^^^^^^^^^^^
  File "C:\Users\91984\AppData\Local\Programs\Python\Python311\Lib\site-packages\django\core\paginator.py", line 93, in count
    return c()
           ^^^
  File "C:\Users\91984\AppData\Local\Programs\Python\Python311\Lib\site-packages\django\db\models\query.py", line 608, in count
    return self.query.get_count(using=self.db)
           ^^^^^^^^^^^^^^^^^^^^^^^^^^^^^^^^^^^
  File "C:\Users\91984\AppData\Local\Programs\Python\Python311\Lib\site-packages\django\db\models\sql\query.py", line 568, in get_count
    return obj.get_aggregation(using, {"__count": Count("*")})["__count"]
           ^^^^^^^^^^^^^^^^^^^^^^^^^^^^^^^^^^^^^^^^^^^^^^^^^^^
  File "C:\Users\91984\AppData\Local\Programs\Python\Python311\Lib\site-packages\django\db\models\sql\query.py", line 554, in get_aggregation
    result = compiler.execute_sql(SINGLE)
             ^^^^^^^^^^^^^^^^^^^^^^^^^^^^
  File "C:\Users\91984\AppData\Local\Programs\Python\Python311\Lib\site-packages\django\db\models\sql\compiler.py", line 1562, in execute_sql
    cursor.execute(sql, params)
  File "C:\Users\91984\AppData\Local\Programs\Python\Python311\Lib\site-packages\django\db\backends\utils.py", line 102, in execute
    return super().execute(sql, params)
           ^^^^^^^^^^^^^^^^^^^^^^^^^^^^
  File "C:\Users\91984\AppData\Local\Programs\Python\Python311\Lib\site-packages\django\db\backends\utils.py", line 67, in execute
    return self._execute_with_wrappers(
           ^^^^^^^^^^^^^^^^^^^^^^^^^^^^
  File "C:\Users\91984\AppData\Local\Programs\Python\Python311\Lib\site-packages\django\db\backends\utils.py", line 80, in _execute_with_wrappers
    return executor(sql, params, many, context)
           ^^^^^^^^^^^^^^^^^^^^^^^^^^^^^^^^^^^^
  File "C:\Users\91984\AppData\Local\Programs\Python\Python311\Lib\site-packages\django\db\backends\utils.py", line 84, in _execute
    with self.db.wrap_database_errors:
  File "C:\Users\91984\AppData\Local\Programs\Python\Python311\Lib\site-packages\django\db\utils.py", line 91, in __exit__
    raise dj_exc_value.with_traceback(traceback) from exc_value
  File "C:\Users\91984\AppData\Local\Programs\Python\Python311\Lib\site-packages\django\db\backends\utils.py", line 89, in _execute
    return self.cursor.execute(sql, params)
           ^^^^^^^^^^^^^^^^^^^^^^^^^^^^^^^^
  File "C:\Users\91984\AppData\Local\Programs\Python\Python311\Lib\site-packages\django\db\backends\sqlite3\base.py", line 328, in execute
    return super().execute(query, params)
           ^^^^^^^^^^^^^^^^^^^^^^^^^^^^^^
django.db.utils.OperationalError: no such table: hardware_api_systemmetric
2025-04-01 15:32:18,395 - ERROR - Error loading model: no such table: hardware_api_modeltraininghistory
2025-04-01 15:32:33,206 - ERROR - Error loading model: no such table: hardware_api_modeltraininghistory
2025-04-01 15:32:47,225 - WARNING - Not Found: /api/metrics/latest/
2025-04-01 15:32:47,824 - ERROR - Internal Server Error: /api/dashboard/
Traceback (most recent call last):
  File "C:\Users\91984\AppData\Local\Programs\Python\Python311\Lib\site-packages\django\core\handlers\exception.py", line 55, in inner
    response = get_response(request)
               ^^^^^^^^^^^^^^^^^^^^^
  File "C:\Users\91984\AppData\Local\Programs\Python\Python311\Lib\site-packages\django\core\handlers\base.py", line 197, in _get_response
    response = wrapped_callback(request, *callback_args, **callback_kwargs)
               ^^^^^^^^^^^^^^^^^^^^^^^^^^^^^^^^^^^^^^^^^^^^^^^^^^^^^^^^^^^^
  File "C:\Users\91984\AppData\Local\Programs\Python\Python311\Lib\site-packages\django\views\decorators\csrf.py", line 56, in wrapper_view
    return view_func(*args, **kwargs)
           ^^^^^^^^^^^^^^^^^^^^^^^^^^
  File "C:\Users\91984\AppData\Local\Programs\Python\Python311\Lib\site-packages\django\views\generic\base.py", line 104, in view
    return self.dispatch(request, *args, **kwargs)
           ^^^^^^^^^^^^^^^^^^^^^^^^^^^^^^^^^^^^^^^
  File "C:\Users\91984\AppData\Local\Programs\Python\Python311\Lib\site-packages\rest_framework\views.py", line 509, in dispatch
    response = self.handle_exception(exc)
               ^^^^^^^^^^^^^^^^^^^^^^^^^^
  File "C:\Users\91984\AppData\Local\Programs\Python\Python311\Lib\site-packages\rest_framework\views.py", line 469, in handle_exception
    self.raise_uncaught_exception(exc)
  File "C:\Users\91984\AppData\Local\Programs\Python\Python311\Lib\site-packages\rest_framework\views.py", line 480, in raise_uncaught_exception
    raise exc
  File "C:\Users\91984\AppData\Local\Programs\Python\Python311\Lib\site-packages\rest_framework\views.py", line 506, in dispatch
    response = handler(request, *args, **kwargs)
               ^^^^^^^^^^^^^^^^^^^^^^^^^^^^^^^^^
  File "C:\Users\91984\Downloads\CSSS\hardware_monitor_project\hardware_monitor_backend\hardware_api\views.py", line 360, in get
    serializer = SystemSummarySerializer(summary)
                 ^^^^^^^^^^^^^^^^^^^^^^^
NameError: name 'SystemSummarySerializer' is not defined
2025-04-01 15:32:49,216 - ERROR - Internal Server Error: /api/dashboard/
Traceback (most recent call last):
  File "C:\Users\91984\AppData\Local\Programs\Python\Python311\Lib\site-packages\django\core\handlers\exception.py", line 55, in inner
    response = get_response(request)
               ^^^^^^^^^^^^^^^^^^^^^
  File "C:\Users\91984\AppData\Local\Programs\Python\Python311\Lib\site-packages\django\core\handlers\base.py", line 197, in _get_response
    response = wrapped_callback(request, *callback_args, **callback_kwargs)
               ^^^^^^^^^^^^^^^^^^^^^^^^^^^^^^^^^^^^^^^^^^^^^^^^^^^^^^^^^^^^
  File "C:\Users\91984\AppData\Local\Programs\Python\Python311\Lib\site-packages\django\views\decorators\csrf.py", line 56, in wrapper_view
    return view_func(*args, **kwargs)
           ^^^^^^^^^^^^^^^^^^^^^^^^^^
  File "C:\Users\91984\AppData\Local\Programs\Python\Python311\Lib\site-packages\django\views\generic\base.py", line 104, in view
    return self.dispatch(request, *args, **kwargs)
           ^^^^^^^^^^^^^^^^^^^^^^^^^^^^^^^^^^^^^^^
  File "C:\Users\91984\AppData\Local\Programs\Python\Python311\Lib\site-packages\rest_framework\views.py", line 509, in dispatch
    response = self.handle_exception(exc)
               ^^^^^^^^^^^^^^^^^^^^^^^^^^
  File "C:\Users\91984\AppData\Local\Programs\Python\Python311\Lib\site-packages\rest_framework\views.py", line 469, in handle_exception
    self.raise_uncaught_exception(exc)
  File "C:\Users\91984\AppData\Local\Programs\Python\Python311\Lib\site-packages\rest_framework\views.py", line 480, in raise_uncaught_exception
    raise exc
  File "C:\Users\91984\AppData\Local\Programs\Python\Python311\Lib\site-packages\rest_framework\views.py", line 506, in dispatch
    response = handler(request, *args, **kwargs)
               ^^^^^^^^^^^^^^^^^^^^^^^^^^^^^^^^^
  File "C:\Users\91984\Downloads\CSSS\hardware_monitor_project\hardware_monitor_backend\hardware_api\views.py", line 360, in get
    serializer = SystemSummarySerializer(summary)
                 ^^^^^^^^^^^^^^^^^^^^^^^
NameError: name 'SystemSummarySerializer' is not defined
2025-04-01 15:33:16,751 - ERROR - Internal Server Error: /api/dashboard/
Traceback (most recent call last):
  File "C:\Users\91984\AppData\Local\Programs\Python\Python311\Lib\site-packages\django\core\handlers\exception.py", line 55, in inner
    response = get_response(request)
               ^^^^^^^^^^^^^^^^^^^^^
  File "C:\Users\91984\AppData\Local\Programs\Python\Python311\Lib\site-packages\django\core\handlers\base.py", line 197, in _get_response
    response = wrapped_callback(request, *callback_args, **callback_kwargs)
               ^^^^^^^^^^^^^^^^^^^^^^^^^^^^^^^^^^^^^^^^^^^^^^^^^^^^^^^^^^^^
  File "C:\Users\91984\AppData\Local\Programs\Python\Python311\Lib\site-packages\django\views\decorators\csrf.py", line 56, in wrapper_view
    return view_func(*args, **kwargs)
           ^^^^^^^^^^^^^^^^^^^^^^^^^^
  File "C:\Users\91984\AppData\Local\Programs\Python\Python311\Lib\site-packages\django\views\generic\base.py", line 104, in view
    return self.dispatch(request, *args, **kwargs)
           ^^^^^^^^^^^^^^^^^^^^^^^^^^^^^^^^^^^^^^^
  File "C:\Users\91984\AppData\Local\Programs\Python\Python311\Lib\site-packages\rest_framework\views.py", line 509, in dispatch
    response = self.handle_exception(exc)
               ^^^^^^^^^^^^^^^^^^^^^^^^^^
  File "C:\Users\91984\AppData\Local\Programs\Python\Python311\Lib\site-packages\rest_framework\views.py", line 469, in handle_exception
    self.raise_uncaught_exception(exc)
  File "C:\Users\91984\AppData\Local\Programs\Python\Python311\Lib\site-packages\rest_framework\views.py", line 480, in raise_uncaught_exception
    raise exc
  File "C:\Users\91984\AppData\Local\Programs\Python\Python311\Lib\site-packages\rest_framework\views.py", line 506, in dispatch
    response = handler(request, *args, **kwargs)
               ^^^^^^^^^^^^^^^^^^^^^^^^^^^^^^^^^
  File "C:\Users\91984\Downloads\CSSS\hardware_monitor_project\hardware_monitor_backend\hardware_api\views.py", line 360, in get
    serializer = SystemSummarySerializer(summary)
                 ^^^^^^^^^^^^^^^^^^^^^^^
NameError: name 'SystemSummarySerializer' is not defined
2025-04-01 15:33:40,640 - INFO - C:\Users\91984\Downloads\CSSS\hardware_monitor_project\hardware_monitor_backend\hardware_api\serializers.py changed, reloading.
2025-04-01 15:33:56,523 - INFO - C:\Users\91984\Downloads\CSSS\hardware_monitor_project\hardware_monitor_backend\hardware_api\views.py changed, reloading.
2025-04-01 15:34:03,209 - INFO - C:\Users\91984\Downloads\CSSS\hardware_monitor_project\hardware_monitor_backend\hardware_api\views.py changed, reloading.
2025-04-01 15:34:15,358 - INFO - C:\Users\91984\Downloads\CSSS\hardware_monitor_project\hardware_monitor_backend\hardware_api\serializers.py changed, reloading.
2025-04-01 15:34:29,445 - ERROR - Internal Server Error: /api/metrics/statistics/
Traceback (most recent call last):
  File "C:\Users\91984\AppData\Local\Programs\Python\Python311\Lib\site-packages\django\core\handlers\exception.py", line 55, in inner
    response = get_response(request)
               ^^^^^^^^^^^^^^^^^^^^^
  File "C:\Users\91984\AppData\Local\Programs\Python\Python311\Lib\site-packages\django\core\handlers\base.py", line 197, in _get_response
    response = wrapped_callback(request, *callback_args, **callback_kwargs)
               ^^^^^^^^^^^^^^^^^^^^^^^^^^^^^^^^^^^^^^^^^^^^^^^^^^^^^^^^^^^^
  File "C:\Users\91984\AppData\Local\Programs\Python\Python311\Lib\site-packages\django\views\decorators\csrf.py", line 56, in wrapper_view
    return view_func(*args, **kwargs)
           ^^^^^^^^^^^^^^^^^^^^^^^^^^
  File "C:\Users\91984\AppData\Local\Programs\Python\Python311\Lib\site-packages\rest_framework\viewsets.py", line 125, in view
    return self.dispatch(request, *args, **kwargs)
           ^^^^^^^^^^^^^^^^^^^^^^^^^^^^^^^^^^^^^^^
  File "C:\Users\91984\AppData\Local\Programs\Python\Python311\Lib\site-packages\rest_framework\views.py", line 509, in dispatch
    response = self.handle_exception(exc)
               ^^^^^^^^^^^^^^^^^^^^^^^^^^
  File "C:\Users\91984\AppData\Local\Programs\Python\Python311\Lib\site-packages\rest_framework\views.py", line 469, in handle_exception
    self.raise_uncaught_exception(exc)
  File "C:\Users\91984\AppData\Local\Programs\Python\Python311\Lib\site-packages\rest_framework\views.py", line 480, in raise_uncaught_exception
    raise exc
  File "C:\Users\91984\AppData\Local\Programs\Python\Python311\Lib\site-packages\rest_framework\views.py", line 506, in dispatch
    response = handler(request, *args, **kwargs)
               ^^^^^^^^^^^^^^^^^^^^^^^^^^^^^^^^^
  File "C:\Users\91984\Downloads\CSSS\hardware_monitor_project\hardware_monitor_backend\hardware_api\views.py", line 257, in statistics
    anomaly_count=Count('id', filter=models.Q(is_anomaly=True))
                                     ^^^^^^
NameError: name 'models' is not defined
2025-04-01 15:34:29,565 - ERROR - Internal Server Error: /api/metrics/statistics/
Traceback (most recent call last):
  File "C:\Users\91984\AppData\Local\Programs\Python\Python311\Lib\site-packages\django\core\handlers\exception.py", line 55, in inner
    response = get_response(request)
               ^^^^^^^^^^^^^^^^^^^^^
  File "C:\Users\91984\AppData\Local\Programs\Python\Python311\Lib\site-packages\django\core\handlers\base.py", line 197, in _get_response
    response = wrapped_callback(request, *callback_args, **callback_kwargs)
               ^^^^^^^^^^^^^^^^^^^^^^^^^^^^^^^^^^^^^^^^^^^^^^^^^^^^^^^^^^^^
  File "C:\Users\91984\AppData\Local\Programs\Python\Python311\Lib\site-packages\django\views\decorators\csrf.py", line 56, in wrapper_view
    return view_func(*args, **kwargs)
           ^^^^^^^^^^^^^^^^^^^^^^^^^^
  File "C:\Users\91984\AppData\Local\Programs\Python\Python311\Lib\site-packages\rest_framework\viewsets.py", line 125, in view
    return self.dispatch(request, *args, **kwargs)
           ^^^^^^^^^^^^^^^^^^^^^^^^^^^^^^^^^^^^^^^
  File "C:\Users\91984\AppData\Local\Programs\Python\Python311\Lib\site-packages\rest_framework\views.py", line 509, in dispatch
    response = self.handle_exception(exc)
               ^^^^^^^^^^^^^^^^^^^^^^^^^^
  File "C:\Users\91984\AppData\Local\Programs\Python\Python311\Lib\site-packages\rest_framework\views.py", line 469, in handle_exception
    self.raise_uncaught_exception(exc)
  File "C:\Users\91984\AppData\Local\Programs\Python\Python311\Lib\site-packages\rest_framework\views.py", line 480, in raise_uncaught_exception
    raise exc
  File "C:\Users\91984\AppData\Local\Programs\Python\Python311\Lib\site-packages\rest_framework\views.py", line 506, in dispatch
    response = handler(request, *args, **kwargs)
               ^^^^^^^^^^^^^^^^^^^^^^^^^^^^^^^^^
  File "C:\Users\91984\Downloads\CSSS\hardware_monitor_project\hardware_monitor_backend\hardware_api\views.py", line 257, in statistics
    anomaly_count=Count('id', filter=models.Q(is_anomaly=True))
                                     ^^^^^^
NameError: name 'models' is not defined
2025-04-01 15:35:30,049 - ERROR - Internal Server Error: /api/metrics/statistics/
Traceback (most recent call last):
  File "C:\Users\91984\AppData\Local\Programs\Python\Python311\Lib\site-packages\django\core\handlers\exception.py", line 55, in inner
    response = get_response(request)
               ^^^^^^^^^^^^^^^^^^^^^
  File "C:\Users\91984\AppData\Local\Programs\Python\Python311\Lib\site-packages\django\core\handlers\base.py", line 197, in _get_response
    response = wrapped_callback(request, *callback_args, **callback_kwargs)
               ^^^^^^^^^^^^^^^^^^^^^^^^^^^^^^^^^^^^^^^^^^^^^^^^^^^^^^^^^^^^
  File "C:\Users\91984\AppData\Local\Programs\Python\Python311\Lib\site-packages\django\views\decorators\csrf.py", line 56, in wrapper_view
    return view_func(*args, **kwargs)
           ^^^^^^^^^^^^^^^^^^^^^^^^^^
  File "C:\Users\91984\AppData\Local\Programs\Python\Python311\Lib\site-packages\rest_framework\viewsets.py", line 125, in view
    return self.dispatch(request, *args, **kwargs)
           ^^^^^^^^^^^^^^^^^^^^^^^^^^^^^^^^^^^^^^^
  File "C:\Users\91984\AppData\Local\Programs\Python\Python311\Lib\site-packages\rest_framework\views.py", line 509, in dispatch
    response = self.handle_exception(exc)
               ^^^^^^^^^^^^^^^^^^^^^^^^^^
  File "C:\Users\91984\AppData\Local\Programs\Python\Python311\Lib\site-packages\rest_framework\views.py", line 469, in handle_exception
    self.raise_uncaught_exception(exc)
  File "C:\Users\91984\AppData\Local\Programs\Python\Python311\Lib\site-packages\rest_framework\views.py", line 480, in raise_uncaught_exception
    raise exc
  File "C:\Users\91984\AppData\Local\Programs\Python\Python311\Lib\site-packages\rest_framework\views.py", line 506, in dispatch
    response = handler(request, *args, **kwargs)
               ^^^^^^^^^^^^^^^^^^^^^^^^^^^^^^^^^
  File "C:\Users\91984\Downloads\CSSS\hardware_monitor_project\hardware_monitor_backend\hardware_api\views.py", line 257, in statistics
    anomaly_count=Count('id', filter=models.Q(is_anomaly=True))
                                     ^^^^^^
NameError: name 'models' is not defined
2025-04-01 15:35:30,097 - ERROR - Internal Server Error: /api/metrics/statistics/
Traceback (most recent call last):
  File "C:\Users\91984\AppData\Local\Programs\Python\Python311\Lib\site-packages\django\core\handlers\exception.py", line 55, in inner
    response = get_response(request)
               ^^^^^^^^^^^^^^^^^^^^^
  File "C:\Users\91984\AppData\Local\Programs\Python\Python311\Lib\site-packages\django\core\handlers\base.py", line 197, in _get_response
    response = wrapped_callback(request, *callback_args, **callback_kwargs)
               ^^^^^^^^^^^^^^^^^^^^^^^^^^^^^^^^^^^^^^^^^^^^^^^^^^^^^^^^^^^^
  File "C:\Users\91984\AppData\Local\Programs\Python\Python311\Lib\site-packages\django\views\decorators\csrf.py", line 56, in wrapper_view
    return view_func(*args, **kwargs)
           ^^^^^^^^^^^^^^^^^^^^^^^^^^
  File "C:\Users\91984\AppData\Local\Programs\Python\Python311\Lib\site-packages\rest_framework\viewsets.py", line 125, in view
    return self.dispatch(request, *args, **kwargs)
           ^^^^^^^^^^^^^^^^^^^^^^^^^^^^^^^^^^^^^^^
  File "C:\Users\91984\AppData\Local\Programs\Python\Python311\Lib\site-packages\rest_framework\views.py", line 509, in dispatch
    response = self.handle_exception(exc)
               ^^^^^^^^^^^^^^^^^^^^^^^^^^
  File "C:\Users\91984\AppData\Local\Programs\Python\Python311\Lib\site-packages\rest_framework\views.py", line 469, in handle_exception
    self.raise_uncaught_exception(exc)
  File "C:\Users\91984\AppData\Local\Programs\Python\Python311\Lib\site-packages\rest_framework\views.py", line 480, in raise_uncaught_exception
    raise exc
  File "C:\Users\91984\AppData\Local\Programs\Python\Python311\Lib\site-packages\rest_framework\views.py", line 506, in dispatch
    response = handler(request, *args, **kwargs)
               ^^^^^^^^^^^^^^^^^^^^^^^^^^^^^^^^^
  File "C:\Users\91984\Downloads\CSSS\hardware_monitor_project\hardware_monitor_backend\hardware_api\views.py", line 257, in statistics
    anomaly_count=Count('id', filter=models.Q(is_anomaly=True))
                                     ^^^^^^
NameError: name 'models' is not defined
2025-04-01 15:36:14,124 - INFO - C:\Users\91984\Downloads\CSSS\hardware_monitor_project\hardware_monitor_backend\hardware_api\views.py changed, reloading.
2025-04-01 15:36:21,254 - INFO - C:\Users\91984\Downloads\CSSS\hardware_monitor_project\hardware_monitor_backend\hardware_api\views.py changed, reloading.
2025-04-01 15:37:49,376 - INFO - C:\Users\91984\Downloads\CSSS\hardware_monitor_project\hardware_monitor_backend\hardware_api\views.py changed, reloading.
2025-04-01 15:38:26,774 - INFO - C:\Users\91984\Downloads\CSSS\hardware_monitor_project\hardware_monitor_backend\hardware_api\views.py changed, reloading.
2025-04-01 15:52:33,390 - INFO - Starting model training
2025-04-01 15:52:33,467 - WARNING - Not enough training data: 1 samples
2025-04-01 15:52:33,477 - ERROR - Internal Server Error: /api/training/train/
2025-04-01 15:54:27,790 - INFO - C:\Users\91984\Downloads\CSSS\hardware_monitor_project\hardware_monitor_backend\hardware_api\views.py changed, reloading.
2025-04-01 15:54:42,439 - INFO - C:\Users\91984\Downloads\CSSS\hardware_monitor_project\hardware_monitor_backend\hardware_api\views.py changed, reloading.
2025-04-01 15:54:50,452 - INFO - C:\Users\91984\Downloads\CSSS\hardware_monitor_project\hardware_monitor_backend\hardware_api\views.py changed, reloading.
2025-04-01 15:55:11,973 - INFO - C:\Users\91984\Downloads\CSSS\hardware_monitor_project\hardware_monitor_backend\hardware_api\views.py changed, reloading.
2025-04-01 15:55:58,989 - INFO - C:\Users\91984\Downloads\CSSS\hardware_monitor_project\hardware_monitor_backend\hardware_api\hardware_monitor.py changed, reloading.
2025-04-01 15:59:14,292 - INFO - Training new model with 1000 samples
2025-04-01 15:59:14,364 - ERROR - Error training model: 'SystemMetric' object has no attribute 'network_sent_bytes'
2025-04-01 15:59:14,364 - ERROR - Model training failed: 'SystemMetric' object has no attribute 'network_sent_bytes'
2025-04-01 15:59:14,480 - ERROR - Traceback (most recent call last):
  File "C:\Users\91984\Downloads\CSSS\hardware_monitor_project\hardware_monitor_backend\hardware_api\views.py", line 331, in train
    result = hardware_monitor.train_anomaly_detection_model(samples)
             ^^^^^^^^^^^^^^^^^^^^^^^^^^^^^^^^^^^^^^^^^^^^^^^^^^^^^^^
  File "C:\Users\91984\Downloads\CSSS\hardware_monitor_project\hardware_monitor_backend\hardware_api\hardware_monitor.py", line 292, in train_anomaly_detection_model
    metric.network_sent_bytes,
    ^^^^^^^^^^^^^^^^^^^^^^^^^
AttributeError: 'SystemMetric' object has no attribute 'network_sent_bytes'

2025-04-01 15:59:14,504 - ERROR - Internal Server Error: /api/training/train/
2025-04-01 15:59:45,213 - WARNING - Method Not Allowed: /api/training/train/
2025-04-01 16:14:18,791 - INFO - C:\Users\91984\Downloads\CSSS\hardware_monitor_project\hardware_monitor_backend\hardware_api\urls.py changed, reloading.
2025-04-01 16:14:35,086 - INFO - C:\Users\91984\Downloads\CSSS\hardware_monitor_project\hardware_monitor_backend\hardware_api\views.py changed, reloading.
2025-04-01 16:25:47,788 - INFO - C:\Users\91984\Downloads\CSSS\hardware_monitor_project\hardware_monitor_backend\hardware_api\views.py changed, reloading.
2025-04-01 16:26:02,019 - INFO - C:\Users\91984\Downloads\CSSS\hardware_monitor_project\hardware_monitor_backend\hardware_api\views.py changed, reloading.
2025-04-01 16:27:53,773 - INFO - C:\Users\91984\Downloads\CSSS\hardware_monitor_project\hardware_monitor_backend\hardware_api\views.py changed, reloading.
2025-04-01 16:28:32,163 - INFO - C:\Users\91984\Downloads\CSSS\hardware_monitor_project\hardware_monitor_backend\hardware_api\views.py changed, reloading.
2025-04-01 16:28:41,338 - INFO - C:\Users\91984\Downloads\CSSS\hardware_monitor_project\hardware_monitor_backend\hardware_api\views.py changed, reloading.
2025-04-01 16:28:49,852 - INFO - C:\Users\91984\Downloads\CSSS\hardware_monitor_project\hardware_monitor_backend\hardware_api\views.py changed, reloading.
2025-04-01 16:29:08,206 - INFO - C:\Users\91984\Downloads\CSSS\hardware_monitor_project\hardware_monitor_backend\hardware_api\views.py changed, reloading.
2025-04-01 16:29:18,193 - INFO - C:\Users\91984\Downloads\CSSS\hardware_monitor_project\hardware_monitor_backend\hardware_api\views.py changed, reloading.
2025-04-01 18:17:17,530 - ERROR - Error getting battery info: <unknown>.Manufacturer
2025-04-01 18:17:17,540 - ERROR - Error getting system info: <x_wmi: WMI returned a syntax error: you're probably running inside a thread without first calling pythoncom.CoInitialize[Ex] (no underlying exception)>
2025-04-01 18:17:17,744 - ERROR - Error getting CPU info: <x_wmi: WMI returned a syntax error: you're probably running inside a thread without first calling pythoncom.CoInitialize[Ex] (no underlying exception)>
2025-04-01 18:17:17,755 - ERROR - Error getting storage info: <x_wmi: WMI returned a syntax error: you're probably running inside a thread without first calling pythoncom.CoInitialize[Ex] (no underlying exception)>
2025-04-01 18:17:17,871 - ERROR - Error getting battery info: <x_wmi: WMI returned a syntax error: you're probably running inside a thread without first calling pythoncom.CoInitialize[Ex] (no underlying exception)>
2025-04-01 18:18:24,429 - ERROR - Error getting system info: <x_wmi: WMI returned a syntax error: you're probably running inside a thread without first calling pythoncom.CoInitialize[Ex] (no underlying exception)>
2025-04-01 18:18:24,631 - ERROR - Error getting CPU info: <x_wmi: WMI returned a syntax error: you're probably running inside a thread without first calling pythoncom.CoInitialize[Ex] (no underlying exception)>
2025-04-01 18:18:24,654 - ERROR - Error getting storage info: <x_wmi: WMI returned a syntax error: you're probably running inside a thread without first calling pythoncom.CoInitialize[Ex] (no underlying exception)>
2025-04-01 18:18:27,815 - ERROR - Error getting battery info: <x_wmi: WMI returned a syntax error: you're probably running inside a thread without first calling pythoncom.CoInitialize[Ex] (no underlying exception)>
2025-04-01 18:18:33,025 - ERROR - Error getting system info: <x_wmi: WMI returned a syntax error: you're probably running inside a thread without first calling pythoncom.CoInitialize[Ex] (no underlying exception)>
2025-04-01 18:18:33,247 - ERROR - Error getting CPU info: <x_wmi: WMI returned a syntax error: you're probably running inside a thread without first calling pythoncom.CoInitialize[Ex] (no underlying exception)>
2025-04-01 18:18:33,326 - ERROR - Error getting storage info: <x_wmi: WMI returned a syntax error: you're probably running inside a thread without first calling pythoncom.CoInitialize[Ex] (no underlying exception)>
2025-04-01 18:18:37,297 - ERROR - Error getting battery info: <x_wmi: WMI returned a syntax error: you're probably running inside a thread without first calling pythoncom.CoInitialize[Ex] (no underlying exception)>
2025-04-01 18:18:37,485 - ERROR - Error getting system info: <x_wmi: WMI returned a syntax error: you're probably running inside a thread without first calling pythoncom.CoInitialize[Ex] (no underlying exception)>
2025-04-01 18:18:37,786 - ERROR - Error getting CPU info: <x_wmi: WMI returned a syntax error: you're probably running inside a thread without first calling pythoncom.CoInitialize[Ex] (no underlying exception)>
2025-04-01 18:18:37,848 - ERROR - Error getting storage info: <x_wmi: WMI returned a syntax error: you're probably running inside a thread without first calling pythoncom.CoInitialize[Ex] (no underlying exception)>
2025-04-01 18:18:39,951 - ERROR - Error getting battery info: <x_wmi: WMI returned a syntax error: you're probably running inside a thread without first calling pythoncom.CoInitialize[Ex] (no underlying exception)>
2025-04-01 18:19:20,837 - ERROR - Error getting system info: <x_wmi: WMI returned a syntax error: you're probably running inside a thread without first calling pythoncom.CoInitialize[Ex] (no underlying exception)>
2025-04-01 18:19:21,050 - ERROR - Error getting CPU info: <x_wmi: WMI returned a syntax error: you're probably running inside a thread without first calling pythoncom.CoInitialize[Ex] (no underlying exception)>
2025-04-01 18:19:21,100 - ERROR - Error getting storage info: <x_wmi: WMI returned a syntax error: you're probably running inside a thread without first calling pythoncom.CoInitialize[Ex] (no underlying exception)>
2025-04-01 18:19:21,664 - ERROR - Error getting battery info: <x_wmi: WMI returned a syntax error: you're probably running inside a thread without first calling pythoncom.CoInitialize[Ex] (no underlying exception)>
2025-04-01 18:19:22,470 - ERROR - Error getting system info: <x_wmi: WMI returned a syntax error: you're probably running inside a thread without first calling pythoncom.CoInitialize[Ex] (no underlying exception)>
2025-04-01 18:19:22,709 - ERROR - Error getting CPU info: <x_wmi: WMI returned a syntax error: you're probably running inside a thread without first calling pythoncom.CoInitialize[Ex] (no underlying exception)>
2025-04-01 18:19:22,738 - ERROR - Error getting storage info: <x_wmi: WMI returned a syntax error: you're probably running inside a thread without first calling pythoncom.CoInitialize[Ex] (no underlying exception)>
2025-04-01 18:19:23,066 - ERROR - Error getting battery info: <x_wmi: WMI returned a syntax error: you're probably running inside a thread without first calling pythoncom.CoInitialize[Ex] (no underlying exception)>
2025-04-01 18:19:52,806 - ERROR - Error getting system info: <x_wmi: WMI returned a syntax error: you're probably running inside a thread without first calling pythoncom.CoInitialize[Ex] (no underlying exception)>
2025-04-01 18:19:53,008 - ERROR - Error getting CPU info: <x_wmi: WMI returned a syntax error: you're probably running inside a thread without first calling pythoncom.CoInitialize[Ex] (no underlying exception)>
2025-04-01 18:19:53,027 - ERROR - Error getting storage info: <x_wmi: WMI returned a syntax error: you're probably running inside a thread without first calling pythoncom.CoInitialize[Ex] (no underlying exception)>
2025-04-01 18:19:53,161 - ERROR - Error getting battery info: <x_wmi: WMI returned a syntax error: you're probably running inside a thread without first calling pythoncom.CoInitialize[Ex] (no underlying exception)>
2025-04-01 18:19:53,174 - ERROR - Error getting system info: <x_wmi: WMI returned a syntax error: you're probably running inside a thread without first calling pythoncom.CoInitialize[Ex] (no underlying exception)>
2025-04-01 18:19:53,417 - ERROR - Error getting CPU info: <x_wmi: WMI returned a syntax error: you're probably running inside a thread without first calling pythoncom.CoInitialize[Ex] (no underlying exception)>
2025-04-01 18:19:53,443 - ERROR - Error getting storage info: <x_wmi: WMI returned a syntax error: you're probably running inside a thread without first calling pythoncom.CoInitialize[Ex] (no underlying exception)>
2025-04-01 18:19:53,568 - ERROR - Error getting battery info: <x_wmi: WMI returned a syntax error: you're probably running inside a thread without first calling pythoncom.CoInitialize[Ex] (no underlying exception)>
2025-04-01 18:20:59,111 - ERROR - Error getting system info: <x_wmi: WMI returned a syntax error: you're probably running inside a thread without first calling pythoncom.CoInitialize[Ex] (no underlying exception)>
2025-04-01 18:20:59,371 - ERROR - Error getting CPU info: <x_wmi: WMI returned a syntax error: you're probably running inside a thread without first calling pythoncom.CoInitialize[Ex] (no underlying exception)>
2025-04-01 18:20:59,490 - ERROR - Error getting storage info: <x_wmi: WMI returned a syntax error: you're probably running inside a thread without first calling pythoncom.CoInitialize[Ex] (no underlying exception)>
2025-04-01 18:20:59,852 - ERROR - Error getting battery info: <x_wmi: WMI returned a syntax error: you're probably running inside a thread without first calling pythoncom.CoInitialize[Ex] (no underlying exception)>
2025-04-01 18:20:59,866 - ERROR - Error getting system info: <x_wmi: WMI returned a syntax error: you're probably running inside a thread without first calling pythoncom.CoInitialize[Ex] (no underlying exception)>
2025-04-01 18:21:00,068 - ERROR - Error getting CPU info: <x_wmi: WMI returned a syntax error: you're probably running inside a thread without first calling pythoncom.CoInitialize[Ex] (no underlying exception)>
2025-04-01 18:21:00,089 - ERROR - Error getting storage info: <x_wmi: WMI returned a syntax error: you're probably running inside a thread without first calling pythoncom.CoInitialize[Ex] (no underlying exception)>
2025-04-01 18:21:00,266 - ERROR - Error getting battery info: <x_wmi: WMI returned a syntax error: you're probably running inside a thread without first calling pythoncom.CoInitialize[Ex] (no underlying exception)>
2025-04-01 18:43:27,672 - ERROR - Error getting system info: <x_wmi: WMI returned a syntax error: you're probably running inside a thread without first calling pythoncom.CoInitialize[Ex] (no underlying exception)>
2025-04-01 18:43:27,877 - ERROR - Error getting CPU info: <x_wmi: WMI returned a syntax error: you're probably running inside a thread without first calling pythoncom.CoInitialize[Ex] (no underlying exception)>
2025-04-01 18:43:27,942 - ERROR - Error getting storage info: <x_wmi: WMI returned a syntax error: you're probably running inside a thread without first calling pythoncom.CoInitialize[Ex] (no underlying exception)>
2025-04-01 18:43:28,083 - ERROR - Error getting battery info: <x_wmi: WMI returned a syntax error: you're probably running inside a thread without first calling pythoncom.CoInitialize[Ex] (no underlying exception)>
2025-04-01 18:43:28,102 - ERROR - Error getting system info: <x_wmi: WMI returned a syntax error: you're probably running inside a thread without first calling pythoncom.CoInitialize[Ex] (no underlying exception)>
2025-04-01 18:43:28,304 - ERROR - Error getting CPU info: <x_wmi: WMI returned a syntax error: you're probably running inside a thread without first calling pythoncom.CoInitialize[Ex] (no underlying exception)>
2025-04-01 18:43:28,320 - ERROR - Error getting storage info: <x_wmi: WMI returned a syntax error: you're probably running inside a thread without first calling pythoncom.CoInitialize[Ex] (no underlying exception)>
2025-04-01 18:43:28,453 - ERROR - Error getting battery info: <x_wmi: WMI returned a syntax error: you're probably running inside a thread without first calling pythoncom.CoInitialize[Ex] (no underlying exception)>
2025-04-01 18:44:39,404 - INFO - C:\Users\91984\Downloads\CSSS\hardware_monitor_project\hardware_monitor_backend\hardware_api\urls.py changed, reloading.
2025-04-01 18:46:05,709 - INFO - C:\Users\91984\Downloads\CSSS\hardware_monitor_project\hardware_monitor_backend\hardware_api\serializers.py changed, reloading.
2025-04-01 18:46:53,400 - INFO - C:\Users\91984\Downloads\CSSS\hardware_monitor_project\hardware_monitor_backend\hardware_api\views.py changed, reloading.
2025-04-01 18:50:26,765 - WARNING - Not Found: /api/hardware-info/
2025-04-01 18:50:26,792 - WARNING - Not Found: /api/hardware-info/
2025-04-01 18:50:37,536 - WARNING - Not Found: /api/hardware-info/
2025-04-01 18:50:37,556 - WARNING - Not Found: /api/hardware-info/
2025-04-01 18:50:43,298 - INFO - C:\Users\91984\Downloads\CSSS\hardware_monitor_project\hardware_monitor_backend\hardware_api\views.py changed, reloading.
2025-04-01 18:52:22,296 - INFO - C:\Users\91984\Downloads\CSSS\hardware_monitor_project\hardware_monitor_backend\hardware_api\views.py changed, reloading.
2025-04-01 18:53:05,405 - INFO - C:\Users\91984\Downloads\CSSS\hardware_monitor_project\hardware_monitor_backend\hardware_api\views.py changed, reloading.
2025-04-01 18:54:43,769 - INFO - C:\Users\91984\Downloads\CSSS\hardware_monitor_project\hardware_monitor_backend\hardware_api\views.py changed, reloading.
2025-04-01 18:54:56,870 - INFO - C:\Users\91984\Downloads\CSSS\hardware_monitor_project\hardware_monitor_backend\hardware_api\urls.py changed, reloading.
